Workbook

Sheet Дашборд
A1: КОНЦЕРТ: ИТОГОВАЯ ЭКОНОМИКА
A2: Один экран с главными цифрами. Все они пересчитываются автоматически — меняйте вводные на листах «Вводные», «Билеты», «Расходы» и «Маркетинг».
B4: Проект | C4: =Вводные!$B$5 | E4: Дата / площадка | F4: =Вводные!$B$7&" · "&Вводные!$B$8
A6: ГЛАВНЫЕ ЦИФРЫ
B7: Валовой сбор (box office) | C7: =Экономика!$B$9 | E7: Продано билетов, шт | F7: =Экономика!$B$6
B8: Итого расходы (смета + переменные) | C8: =Экономика!$B$26 | E8: Средняя цена платного билета | F8: =Экономика!$B$8
B9: Налоги, РАО и комиссии, всего | C9: =Экономика!$B$15-Экономика!$B$32-Экономика!$B$36 | E9: Дополнительные доходы | F9: =Билеты!$E$32
B10: ПРИБЫЛЬ К РАЗДЕЛУ С ПЛОЩАДКОЙ | C10: =Экономика!$B$29 | E10: ЧИСТЫЙ ДОХОД ОРГАНИЗАТОРА | F10: =Экономика!$B$37
A12: УСТОЙЧИВОСТЬ ПРОЕКТА
B13: Точка безубыточности, платных билетов | C13: =Экономика!$B$41 | E13: Точка безубыточности, % зала | F13: =Экономика!$B$42
B14: Запас прочности | C14: =Экономика!$B$43 | E14: Рентабельность к валовому сбору | F14: =Экономика!$B$44
B15: Маржинальный доход с билета | C15: =Экономика!$B$40 | E15: Чистый доход на один билет | F15: =Экономика!$B$45
B17: ВЕРДИКТ | C17: =Экономика!$B$47
A19: СЦЕНАРИИ — ЧИСТЫЙ ДОХОД ОРГАНИЗАТОРА
B20: Пессимистичный | C20: Базовый | D20: Оптимистичный | E20: Аншлаг
B21: =Сценарии!B23 | C21: =Сценарии!C23 | D21: =Сценарии!D23 | E21: =Сценарии!E23
B22: =Сценарии!B5 | C22: =Сценарии!C5 | D22: =Сценарии!D5 | E22: =Сценарии!E5 | F22: ← заполняемость зала в сценарии
A24: ЧТО ОБЯЗАТЕЛЬНО УТОЧНИТЬ ПЕРЕД ЗАПУСКОМ
B25: 1. Договор с площадкой: что именно входит в её вклад (звук, свет, персонал, охрана, уборка) — впишите это в столбец «Оплачивает» на листе «Расходы».
B26: 2. Договор с площадкой: делится ли убыток. Если нет — весь минус ваш, а плюс только наполовину.
B27: 3. Договор с площадкой: из какой базы считается «прибыль к разделу» и кто подтверждает смету расходов.
B28: 4. Билетный оператор: ставка комиссии и чья это комиссия — покупателя или ваша (схема 1 или 2 на листе «Вводные»).
B29: 5. Билетный оператор: агентская схема или прямая продажа — от этого зависит, вся ли касса попадает в базу УСН.
B30: 6. РАО: ставка по договору и перечень исполняемых произведений (собственные и общественное достояние считаются иначе).
B31: 7. Кто получает деньги от билетов физически — вы или площадка. От этого зависит, у кого возникает доход и на каком уровне удерживается УСН.
B32: 8. Технический райдер артиста — пришлите файл, и я перенесу его построчно в смету с реальными ценами аренды.

Sheet Вводные
A1: ВВОДНЫЕ ДАННЫЕ И ДОПУЩЕНИЯ
A2: Синие ячейки на жёлтом фоне — вводные, их можно и нужно менять. Чёрные — формулы, их менять не нужно. Зелёные — ссылки на другие листы.
A4: 1. ПАРАМЕТРЫ СОБЫТИЯ
A5: Название концерта | B5: — укажите название —
A6: Артист / состав | B6: — укажите —
A7: Дата и время | B7: — ДД.ММ.ГГГГ, 20:00 —
A8: Площадка | B8: — клуб —
A9: Город | B9: — город —
A11: 2. ЗАЛ И ПОСЕЩАЕМОСТЬ
A12: Вместимость зала, чел. | B12: 300 | C12: Клубный формат. Поставьте реальную вместимость по договору с площадкой
A13: Заполняемость — пессимистичный сценарий | B13: 0.4 | C13: Слабый промо, плохая погода, конкурирующее событие в городе
A14: Заполняемость — оптимистичный сценарий | B14: 0.9
A15: Заполняемость — аншлаг | B15: 1 | C15: Базовый сценарий берётся с листа «Билеты» — там задана покатегорийная продажа
A17: 3. БИЛЕТНАЯ ПРОДАЖА
A18: Схема сервисного сбора (1 или 2) | B18: 2 | C18: 1 = сбор платит покупатель сверх цены (вам — полная цена) · 2 = комиссия удерживается из цены (расход организатора)
A19: Комиссия билетного оператора, % | B19: 0.1 | C19: Рынок: 5–12% от номинала. Уточните в договоре с оператором
A20: Доля продаж на входе / напрямую, % | B20: 0.15 | C20: На эту часть комиссия оператора не начисляется
A22: 4. НАЛОГИ, СБОРЫ И ОТЧИСЛЕНИЯ
A23: УРОВЕНЬ 1 — с валового сбора (до раздела прибыли)
A24: УСН «доходы», % | B24: 0.06 | C24: На первом уровне удерживается только УСН 6%
A25: ИТОГО фискальная нагрузка, уровень 1 | B25: =Вводные!$B$24 | C25: Удерживается с валового сбора до вычета расходов и раздела прибыли
A26: Отчисления в РАО, % | B26: 0.05 | C26: Стандартная ставка для концертов — 5% от валового сбора
A28: УРОВЕНЬ 2 — с выплаты доли прибыли организатору
A29: УСН «доходы» с выплаты, % | B29: 0.06
A30: Страховые взносы (1% с дохода), % | B30: 0.01
A31: Банковские комиссии / эквайринг, % | B31: 0.01
A32: ИТОГО фискальная нагрузка, уровень 2 | B32: =Вводные!$B$29+Вводные!$B$30+Вводные!$B$31 | C32: 6% + 1% + 1% = 8% — удерживается с выплаты прибыли по договору с площадкой
A34: 5. РАЗДЕЛ ПРИБЫЛИ С ПЛОЩАДКОЙ
A35: Доля организатора в прибыли, % | B35: 0.5
A36: Доля площадки в прибыли, % | B36: =1-Вводные!$B$35
A37: Убыток делится с площадкой? (Да/Нет) | B37: Нет | C37: КРИТИЧНО: если «Нет» — весь убыток на вас. Пропишите это в договоре явно
A38: Доп. доходы участвуют в разделе? (Да/Нет) | B38: Нет | C38: Мерч, спонсорство, донаты — обычно остаются у организатора целиком
A40: 6. ПРОЧЕЕ
A41: Переменные расходы на гостя, ₽ | B41: 60 | C41: Браслет, печать билета, гардеробный номерок, вода
A42: Резерв на непредвиденное, % от сметы | B42: 0.1 | C42: Ниже 10% ставить не рекомендую — всегда вылезает что-то неучтённое

Sheet Билеты
A1: БИЛЕТНАЯ МАТРИЦА И ДОПОЛНИТЕЛЬНЫЕ ДОХОДЫ
A2: Базовый сценарий строится именно здесь: задайте цены, квоты мест и ожидаемый процент продажи по каждой категории.
A4: СТРУКТУРА БИЛЕТОВ
A5: Категория билета | B5: Цена, ₽ | C5: Квота, мест | D5: Ожид. продажа, % | E5: Продано, шт | F5: Валовой сбор, ₽ | G5: Доля в сборе | H5: Комментарий
A6: Ранняя пташка (early bird) | B6: 1800 | C6: 60 | D6: 0.95 | E6: =ROUND(C6*D6,0) | F6: =B6*E6 | G6: =IFERROR(F6/$F$12,0) | H6: Первые 2 недели, ограниченная квота. Даёт ранний денежный поток на маркетинг
A7: Стандарт (предпродажа) | B7: 2500 | C7: 150 | D7: 0.6 | E7: =ROUND(C7*D7,0) | F7: =B7*E7 | G7: =IFERROR(F7/$F$12,0) | H7: Основная квота зала
A8: Стандарт (на входе, в день концерта) | B8: 2800 | C8: 40 | D8: 0.5 | E8: =ROUND(C8*D8,0) | F8: =B8*E8 | G8: =IFERROR(F8/$F$12,0) | H8: Цена на входе выше — это стимул покупать заранее
A9: Фан-зона у сцены / VIP | B9: 4000 | C9: 30 | D9: 0.6 | E9: =ROUND(C9*D9,0) | F9: =B9*E9 | G9: =IFERROR(F9/$F$12,0) | H9: Первые ряды, отдельный вход, мерч в подарок
A10: Льготный (студенты) | B10: 1500 | C10: 10 | D10: 0.7 | E10: =ROUND(C10*D10,0) | F10: =B10*E10 | G10: =IFERROR(F10/$F$12,0) | H10: Заполняет зал и даёт социальный охват
A11: Промо, пресс, гости артиста | B11: 0 | C11: 10 | D11: 1 | E11: =ROUND(C11*D11,0) | F11: =B11*E11 | G11: =IFERROR(F11/$F$12,0) | H11: Денег не приносят, но занимают места и создают переменные расходы
A12: ИТОГО | C12: =SUM(C6:C11) | E12: =SUM(E6:E11) | F12: =SUM(F6:F11) | G12: =SUM(G6:G11)
A14: КОНТРОЛЬНЫЕ ПОКАЗАТЕЛИ
A15: Проверка: сумма квот = вместимость зала? | B15: =IF(Билеты!$C$12=Вводные!$B$12,"OK — квоты сходятся с залом","ВНИМАНИЕ: квоты ("&Билеты!$C$12&") ≠ вместимость ("&Вводные!$B$12&")")
A16: Продано билетов всего, шт | B16: =Билеты!$E$12
A17: в т.ч. платных, шт | B17: =SUMIF(B6:B11,">0",E6:E11)
A18: в т.ч. бесплатных (промо, пресс), шт | B18: =Билеты!$E$12-Билеты!$B$17
A19: Валовой сбор (box office), ₽ | B19: =Билеты!$F$12
A20: Средняя цена платного билета, ₽ | B20: =IFERROR(Билеты!$F$12/Билеты!$B$17,0)
A21: Доход на одно место зала (yield), ₽ | B21: =IFERROR(Билеты!$F$12/Вводные!$B$12,0) | C21: Ключевая метрика для сравнения площадок и форматов
A22: Фактическая заполняемость зала, % | B22: =IFERROR(Билеты!$E$12/Вводные!$B$12,0)
A23: Доля платных билетов от всех проходов, % | B23: =IFERROR(Билеты!$B$17/Билеты!$E$12,0)
A25: ДОПОЛНИТЕЛЬНЫЕ ДОХОДЫ (не билетные)
A26: Источник дохода | B26: База (шт / ₽) | C26: Ставка, чек, ₽ | D26: Маржа / доля, % | E26: Доход, ₽ | H26: Комментарий
A27: Мерч: футболки, винил, значки | B27: 30 | C27: 2000 | D27: 0.55 | E27: =B27*C27*D27 | H27: Конверсия в мерч 10–20% зала. Продаётся до концерта и на выходе
A28: Доля от выручки бара | B28: 1 | C28: 250000 | D28: 0.1 | E28: =B28*C28*D28 | H28: Часто 10–20% бара. Обязательно прописать в договоре с площадкой
A29: Спонсорский пакет / партнёр | B29: 1 | C29: 0 | D29: 1 | E29: =B29*C29*D29 | H29: Поставьте сумму, если есть партнёр. Самый недооценённый источник — см. лист «Варианты»
A30: Донаты, краудфандинг, предзаказ | B30: 1 | C30: 0 | D30: 1 | E30: =B30*C30*D30 | H30: Сбор до концерта закрывает кассовый разрыв на предоплаты
A31: Съёмка концерта: релиз, стриминг | B31: 1 | C31: 0 | D31: 1 | E31: =B31*C31*D31 | H31: Доход приходит после события — учитывайте отдельно по срокам
A32: ИТОГО дополнительных доходов | E32: =SUM(E27:E31)

Sheet Маркетинг
A1: МАРКЕТИНГ И PR: БЮДЖЕТ, ВОРОНКА, СТОИМОСТЬ БИЛЕТА
A2: Каждый канал считается до билета: охват → отклик → покупка. Так видно, какой канал реально продаёт, а какой только тратит.
A4: КАНАЛЫ ПРОДВИЖЕНИЯ
A5: Канал | B5: Бюджет, ₽ | C5: Прогноз охвата, чел. | D5: Отклик (CTR), % | E5: Конверсия в покупку, % | F5: Прогноз билетов, шт | G5: CPA, ₽ за билет | H5: Комментарий
A6: Таргетированная реклама VK | B6: 25000 | C6: 120000 | D6: 0.012 | E6: 0.03 | F6: =ROUND(C6*D6*E6,0) | G6: =IFERROR(B6/F6,0) | H6: Основной платный канал в РФ. Гео + интересы + look-alike по базе
A7: Посевы в Telegram-каналах | B7: 20000 | C7: 60000 | D7: 0.02 | E7: 0.04 | F7: =ROUND(C7*D7*E7,0) | G7: =IFERROR(B7/F7,0) | H7: Городские и жанровые каналы. Просите статистику охватов до оплаты
A8: Блогеры и лидеры мнений | B8: 15000 | C8: 40000 | D8: 0.025 | E8: 0.035 | F8: =ROUND(C8*D8*E8,0) | G8: =IFERROR(B8/F8,0) | H8: Часть работает по бартеру за билеты — снижает бюджет
A9: Наружная реклама и расклейка афиш | B9: 10000 | C9: 30000 | D9: 0.005 | E9: 0.05 | F9: =ROUND(C9*D9*E9,0) | G9: =IFERROR(B9/F9,0) | H9: Работает на узнавание, плохо атрибутируется. Отдельный промокод обязателен
A10: Городские афиши: Яндекс.Афиша, KudaGo | B10: 0 | C10: 25000 | D10: 0.01 | E10: 0.04 | F10: =ROUND(C10*D10*E10,0) | G10: =IFERROR(B10/F10,0) | H10: Бесплатное размещение. Подавать за 3–4 недели
A11: PR: пресс-релиз, СМИ, интервью | B11: 8000 | C11: 20000 | D11: 0.01 | E11: 0.03 | F11: =ROUND(C11*D11*E11,0) | G11: =IFERROR(B11/F11,0) | H11: Даёт доверие и вторичные перепечатки, а не прямые продажи
A12: Email и база подписчиков | B12: 2000 | C12: 5000 | D12: 0.12 | E12: 0.08 | F12: =ROUND(C12*D12*E12,0) | G12: =IFERROR(B12/F12,0) | H12: Самый дешёвый билет. Базу надо собирать с прошлых концертов
A13: Продакшн контента: дизайн, тизер, фото | B13: 10000 | C13: 0 | D13: 0 | E13: 0 | F13: =ROUND(C13*D13*E13,0) | G13: =IFERROR(B13/F13,0) | H13: Не продаёт напрямую, но без него не работают все каналы выше
A14: ИТОГО МАРКЕТИНГ И PR | B14: =SUM(B6:B13) | C14: =SUM(C6:C13) | F14: =SUM(F6:F13) | G14: =IFERROR(B14/F14,0)
A16: ПРОВЕРКА ЗДОРОВЬЯ МАРКЕТИНГА
A17: Бюджет маркетинга и PR, ₽ | B17: =Маркетинг!$B$14
A18: Прогноз билетов от маркетинга, шт | B18: =Маркетинг!$F$14
A19: План продаж по билетной матрице, шт | B19: =Билеты!$B$17
A20: Покрытие плана продаж маркетингом, % | B20: =IFERROR(Маркетинг!$F$14/Билеты!$B$17,0) | C20: Ниже 100% — план продаж ничем не обеспечен. Выше 130% — можно снять часть бюджета
A21: Средний CPA (стоимость привлечения билета), ₽ | B21: =Маркетинг!$G$14
A22: Средняя цена платного билета, ₽ | B22: =Билеты!$B$20
A23: CPA к цене билета, % | B23: =IFERROR(Маркетинг!$G$14/Билеты!$B$20,0) | C23: Здоровый диапазон — до 25%. Выше 35% — канальная модель не сходится
A24: Доля маркетинга в валовом сборе, % | B24: =IFERROR(Маркетинг!$B$14/Билеты!$F$12,0) | C24: Ориентир для клубного концерта — 10–15%. Выше 20% — бюджет съедает прибыль
A25: Вердикт | B25: =IF(Маркетинг!$B$24>0.2,"ПЕРЕРАСХОД: маркетинг забирает больше 20% сбора",IF(Маркетинг!$B$20<1,"РИСК: маркетинг не покрывает план продаж","Норма: бюджет и план продаж сбалансированы"))

Sheet Расходы
A1: СМЕТА РАСХОДОВ
A2: Столбец «Оплачивает» решает всё: строки со значением «Площадка» показаны по рыночной цене, но в ваши расходы не попадают. Так видно реальный вклад площадки в сделку 50/50.
A4: Статья расхода | B4: Кол-во | C4: Ед. | D4: Цена за ед., ₽ | E4: Сумма организатора, ₽ | F4: Оплачивает | G4: Комментарий
A5: 1. ПЛОЩАДКА И ТЕХНИЧЕСКОЕ ОБЕСПЕЧЕНИЕ
A6: Аренда зала (смена) | B6: 1 | C6: смена | D6: 60000 | E6: =IF($F6="Площадка",0,B6*D6) | F6: Площадка | G6: При сделке 50/50 аренда не выставляется — это вклад площадки
A7: Доп. часы: монтаж и саундчек | B7: 4 | C7: час | D7: 5000 | E7: =IF($F7="Площадка",0,B7*D7) | F7: Площадка | G7: Обычно входит в смену. Обязательно уточните в договоре
A8: Звуковой комплект PA | B8: 1 | C8: компл. | D8: 45000 | E8: =IF($F8="Площадка",0,B8*D8) | F8: Площадка | G8: Штатный аппарат клуба
A9: Доп. микрофоны, радиосистемы, стойки | B9: 1 | C9: компл. | D9: 12000 | E9: =IF($F9="Площадка",0,B9*D9) | F9: Организатор | G9: Под конкретный состав почти всегда докупается в аренду
A10: Мониторная линия / in-ear | B10: 1 | C10: компл. | D10: 15000 | E10: =IF($F10="Площадка",0,B10*D10) | F10: Организатор | G10: Критично для качества исполнения на сцене
A11: Звукорежиссёр FOH (свой) | B11: 1 | C11: смена | D11: 20000 | E11: =IF($F11="Площадка",0,B11*D11) | F11: Организатор | G11: Свой инженер — предсказуемый звук. Клубный — лотерея
A12: Мониторный инженер | B12: 1 | C12: смена | D12: 12000 | E12: =IF($F12="Площадка",0,B12*D12) | F12: Площадка | G12: В клубе часто совмещается с FOH
A13: Световое оборудование | B13: 1 | C13: компл. | D13: 25000 | E13: =IF($F13="Площадка",0,B13*D13) | F13: Площадка | G13: Штатный свет клуба
A14: Художник по свету / оператор | B14: 1 | C14: смена | D14: 12000 | E14: =IF($F14="Площадка",0,B14*D14) | F14: Организатор | G14: Свет под программу, а не «дискотека по кнопке»
A15: Бэклайн: барабаны, усилители, клавиши | B15: 1 | C15: компл. | D15: 20000 | E15: =IF($F15="Площадка",0,B15*D15) | F15: Организатор | G15: По техническому райдеру
A16: Экран, проекция, видеоконтент | B16: 0 | C16: компл. | D16: 18000 | E16: =IF($F16="Площадка",0,B16*D16) | F16: Организатор | G16: Поставьте количество 1, если в программе есть видеоряд
A17: Электрика, кабели, распределение | B17: 1 | C17: компл. | D17: 5000 | E17: =IF($F17="Площадка",0,B17*D17) | F17: Площадка
A18: Монтаж, демонтаж, погрузка | B18: 3 | C18: чел. | D18: 4000 | E18: =IF($F18="Площадка",0,B18*D18) | F18: Организатор | G18: Разгрузка и погрузка бэклайна
A19: Итого по блоку: Площадка и техническое обеспечение | E19: =SUM(E6:E18)
A21: 2. ПЕРСОНАЛ И ОБСЛУЖИВАНИЕ
A22: Администратор площадки | B22: 1 | C22: смена | D22: 10000 | E22: =IF($F22="Площадка",0,B22*D22) | F22: Площадка
A23: Билетный контроль | B23: 2 | C23: чел. | D23: 4000 | E23: =IF($F23="Площадка",0,B23*D23) | F23: Площадка
A24: Гардероб | B24: 2 | C24: чел. | D24: 3500 | E24: =IF($F24="Площадка",0,B24*D24) | F24: Площадка
A25: Охрана | B25: 4 | C25: чел. | D25: 5000 | E25: =IF($F25="Площадка",0,B25*D25) | F25: Площадка | G25: Ориентир — 1 человек на 75–100 гостей
A26: Уборка до и после | B26: 2 | C26: чел. | D26: 3500 | E26: =IF($F26="Площадка",0,B26*D26) | F26: Площадка
A27: Дежурный медик | B27: 1 | C27: смена | D27: 6000 | E27: =IF($F27="Площадка",0,B27*D27) | F27: Площадка | G27: Требование для массовых мероприятий
A28: Фотограф | B28: 1 | C28: смена | D28: 15000 | E28: =IF($F28="Площадка",0,B28*D28) | F28: Организатор | G28: Контент окупается в промо следующего концерта
A29: Видеосъёмка концерта (2 камеры) | B29: 1 | C29: смена | D29: 25000 | E29: =IF($F29="Площадка",0,B29*D29) | F29: Организатор | G29: Материал для клипов, отчётного видео и питчей площадкам
A30: Продюсер / директор проекта | B30: 0 | C30: проект | D30: 30000 | E30: =IF($F30="Площадка",0,B30*D30) | F30: Организатор | G30: Поставьте 1, если проект ведёт наёмный человек, а не вы
A31: Итого по блоку: Персонал и обслуживание | E31: =SUM(E22:E30)
A33: 3. ПРОДАКШН И ЛОГИСТИКА
A34: Репетиции и прогон программы | B34: 2 | C34: смена | D34: 6000 | E34: =IF($F34="Площадка",0,B34*D34) | F34: Организатор | G34: Аренда репетиционной базы
A35: Транспорт оборудования | B35: 2 | C35: рейс | D35: 8000 | E35: =IF($F35="Площадка",0,B35*D35) | F35: Организатор | G35: Туда и обратно
A36: Трансфер и проживание команды | B36: 0 | C36: компл. | D36: 25000 | E36: =IF($F36="Площадка",0,B36*D36) | F36: Организатор | G36: Заполните, если команда не из этого города
A37: Кейтеринг и райдер бэкстейджа | B37: 15 | C37: чел. | D37: 800 | E37: =IF($F37="Площадка",0,B37*D37) | F37: Организатор | G37: По числу людей на площадке, включая техников
A38: Вода, расходники, хозтовары | B38: 1 | C38: компл. | D38: 3000 | E38: =IF($F38="Площадка",0,B38*D38) | F38: Организатор
A39: Полиграфия: афиши, флаеры | B39: 1 | C39: тираж | D39: 12000 | E39: =IF($F39="Площадка",0,B39*D39) | F39: Организатор | G39: Печать. Размещение — в бюджете маркетинга
A40: Бейджи, браслеты, программки | B40: 1 | C40: тираж | D40: 6000 | E40: =IF($F40="Площадка",0,B40*D40) | F40: Организатор
A41: Оформление сцены и зала, декор | B41: 1 | C41: компл. | D41: 15000 | E41: =IF($F41="Площадка",0,B41*D41) | F41: Организатор | G41: Сильно влияет на восприятие и на качество контента
A42: Итого по блоку: Продакшн и логистика | E42: =SUM(E34:E41)
A44: 5. ЮРИДИЧЕСКОЕ, ФИНАНСОВОЕ, ПРОЧЕЕ
...

Sheet Экономика
A1: ЭКОНОМИКА КОНЦЕРТА: ОТ КАССЫ ДО ДЕНЕГ В КАРМАНЕ
A2: Водопад по вашей схеме: УСН 6% с валового сбора → расходы → раздел прибыли с площадкой → 8% (6+1+1) с выплаты вам.
A4: Показатель | B4: Сумма, ₽ | C4: % от сбора | D4: Комментарий
A5: ДОХОДНАЯ ЧАСТЬ
A6: Продано билетов всего, шт | B6: =Билеты!$E$12
A7: в том числе платных, шт | B7: =Билеты!$B$17
A8: Средняя цена платного билета, ₽ | B8: =Билеты!$B$20
A9: ВАЛОВОЙ СБОР (BOX OFFICE) | B9: =Билеты!$F$12 | C9: =IFERROR(B9/$B$9,0) | D9: Вся сумма, которую платят зрители за номинал билета
A10: Сервисный сбор с покупателя (справочно) | B10: =IF(Вводные!$B$18=1,Экономика!$B$9*(1-Вводные!$B$20)*Вводные!$B$19,0) | C10: =IFERROR(B10/$B$9,0) | D10: При схеме 1 это деньги оператора сверх цены — в вашу выручку не входят
A11: ВЫЧЕТЫ ИЗ ВАЛОВОГО СБОРА — УРОВЕНЬ 1
A12: Комиссия билетного оператора | B12: =IF(Вводные!$B$18=2,Экономика!$B$9*(1-Вводные!$B$20)*Вводные!$B$19,0) | C12: =IFERROR(B12/$B$9,0) | D12: При схеме 2 удерживается из цены билета. На продажи «на входе» не начисляется
A13: Отчисления в РАО | B13: =Экономика!$B$9*Вводные!$B$26 | C13: =IFERROR(B13/$B$9,0) | D13: 5% от валового сбора за публичное исполнение произведений
A14: УСН 6% с валового сбора | B14: =Экономика!$B$9*Вводные!$B$25 | C14: =IFERROR(B14/$B$9,0) | D14: Уровень 1: только УСН, без взносов и банковской комиссии
A15: ИТОГО ВЫЧЕТОВ | B15: =Экономика!$B$12+Экономика!$B$13+Экономика!$B$14 | C15: =IFERROR(B15/$B$9,0)
A16: СБОР ПОСЛЕ ВЫЧЕТОВ | B16: =Экономика!$B$9-Экономика!$B$15 | C16: =IFERROR(B16/$B$9,0)
A17: РАСХОДЫ
A18: Площадка и техническое обеспечение | B18: =Расходы!$E$19 | C18: =IFERROR(B18/$B$9,0)
A19: Персонал и обслуживание | B19: =Расходы!$E$31 | C19: =IFERROR(B19/$B$9,0)
A20: Продакшн и логистика | B20: =Расходы!$E$42 | C20: =IFERROR(B20/$B$9,0)
A21: Маркетинг и PR | B21: =Расходы!$E$53 | C21: =IFERROR(B21/$B$9,0) | D21: Детализация по каналам и стоимость привлечения — на листе «Маркетинг»
A22: Юридическое, финансовое, прочее | B22: =Расходы!$E$49 | C22: =IFERROR(B22/$B$9,0)
A23: Резерв на непредвиденное | B23: =Расходы!$E$58-(Расходы!$E$19+Расходы!$E$31+Расходы!$E$42+Расходы!$E$49+Расходы!$E$53) | C23: =IFERROR(B23/$B$9,0)
A24: Итого постоянных расходов | B24: =Расходы!$E$58 | C24: =IFERROR(B24/$B$9,0)
A25: Переменные расходы на гостей | B25: =Экономика!$B$6*Вводные!$B$41 | C25: =IFERROR(B25/$B$9,0) | D25: Браслеты, печать билетов, вода, гардеробные номерки — растут вместе с залом
A26: ИТОГО РАСХОДЫ | B26: =Экономика!$B$24+Экономика!$B$25 | C26: =IFERROR(B26/$B$9,0)
A27: РАЗДЕЛ ПРИБЫЛИ С ПЛОЩАДКОЙ
A28: Доп. доходы, участвующие в разделе (за вычетом УСН 6%) | B28: =IF(Вводные!$B$38="Да",Билеты!$E$32*(1-Вводные!$B$25),0) | C28: =IFERROR(B28/$B$9,0) | D28: Переключатель «Доп. доходы участвуют в разделе» — на листе «Вводные»
A29: ПРИБЫЛЬ К РАЗДЕЛУ | B29: =Экономика!$B$16-Экономика!$B$26+Экономика!$B$28 | C29: =IFERROR(B29/$B$9,0)
A30: Доля площадки | B30: =IF(Экономика!$B$29>=0,Экономика!$B$29*Вводные!$B$36,IF(Вводные!$B$37="Да",Экономика!$B$29*Вводные!$B$36,0)) | C30: =IFERROR(B30/$B$9,0) | D30: Если убыток не делится, площадка не несёт ничего — весь минус ваш
A31: Доля организатора — выплата по договору | B31: =Экономика!$B$29-Экономика!$B$30 | C31: =IFERROR(B31/$B$9,0)
A32: Налог и комиссии с выплаты (уровень 2: 6%+1%+1%) | B32: =-MAX(0,Экономика!$B$31)*Вводные!$B$32 | C32: =IFERROR(B32/$B$9,0) | D32: Выплата от площадки — второй доход, облагается повторно
A33: ЧИСТЫЙ ДОХОД ОРГАНИЗАТОРА ОТ БИЛЕТОВ | B33: =Экономика!$B$31+Экономика!$B$32 | C33: =IFERROR(B33/$B$9,0)
A34: ДОПОЛНИТЕЛЬНЫЕ ДОХОДЫ И ИТОГ
A35: Доп. доходы, остающиеся у организатора | B35: =IF(Вводные!$B$38="Да",0,Билеты!$E$32) | C35: =IFERROR(B35/$B$9,0)
A36: Налоги и комиссии с доп. доходов (8%) | B36: =-Экономика!$B$35*Вводные!$B$32 | C36: =IFERROR(B36/$B$9,0)
A37: ИТОГО ЧИСТЫЙ ДОХОД ОРГАНИЗАТОРА | B37: =Экономика!$B$33+Экономика!$B$35+Экономика!$B$36 | C37: =IFERROR(B37/$B$9,0)
A39: КЛЮЧЕВЫЕ МЕТРИКИ И ТОЧКА БЕЗУБЫТОЧНОСТИ
A40: Маржинальный доход с одного платного билета, ₽ | B40: =Экономика!$B$8*(1-IF(Вводные!$B$18=2,Вводные!$B$19*(1-Вводные!$B$20),0)-Вводные!$B$26-Вводные!$B$25)-IFERROR(Вводные!$B$41/Билеты!$B$23,Вводные!$B$41) | D40: Сколько остаётся с билета до постоянных расходов. Это «скорость», с которой окупается смета
A41: Точка безубыточности, платных билетов | B41: =IF(Экономика!$B$40<=0,"н/д — билет не покрывает переменные расходы",ROUNDUP(Экономика!$B$24/Экономика!$B$40,0)) | D41: Сколько платных билетов надо продать, чтобы выйти в ноль до раздела прибыли
A42: Точка безубыточности, % заполнения зала | B42: =IFERROR(Экономика!$B$41/Билеты!$B$23/Вводные!$B$12,0)
...

Sheet Сценарии
A1: СЦЕНАРИИ: ОТ ПРОВАЛА ДО АНШЛАГА
A2: Структура цен и смета во всех сценариях одинаковые — меняется только заполняемость зала. Последний столбец показывает, где проходит граница нуля.
A4: Показатель | B4: Пессимистичный | C4: БАЗОВЫЙ | D4: Оптимистичный | E4: Аншлаг | F4: Точка безубыточности | G4: Комментарий
A5: Заполняемость зала, % | B5: =Вводные!$B$13 | C5: =Билеты!$B$22 | D5: =Вводные!$B$14 | E5: =Вводные!$B$15 | F5: =Экономика!$B$42 | G5: Пессимистичный и оптимистичный задаются на листе «Вводные»
A6: Продано билетов всего, шт | B6: =ROUND(Вводные!$B$12*B5,0) | C6: =Билеты!$E$12 | D6: =ROUND(Вводные!$B$12*D5,0) | E6: =ROUND(Вводные!$B$12*E5,0) | F6: =ROUND(Вводные!$B$12*F5,0)
A7: в том числе платных, шт | B7: =ROUND(B6*Билеты!$B$23,0) | C7: =Билеты!$B$17 | D7: =ROUND(D6*Билеты!$B$23,0) | E7: =ROUND(E6*Билеты!$B$23,0) | F7: =ROUND(F6*Билеты!$B$23,0)
A8: Средняя цена платного билета, ₽ | B8: =Билеты!$B$20 | C8: =Билеты!$B$20 | D8: =Билеты!$B$20 | E8: =Билеты!$B$20 | F8: =Билеты!$B$20
A9: ВАЛОВОЙ СБОР | B9: =B7*B8 | C9: =Билеты!$F$12 | D9: =D7*D8 | E9: =E7*E8 | F9: =F7*F8
A10: − комиссия билетного оператора | B10: =-IF(Вводные!$B$18=2,B9*(1-Вводные!$B$20)*Вводные!$B$19,0) | C10: =-IF(Вводные!$B$18=2,C9*(1-Вводные!$B$20)*Вводные!$B$19,0) | D10: =-IF(Вводные!$B$18=2,D9*(1-Вводные!$B$20)*Вводные!$B$19,0) | E10: =-IF(Вводные!$B$18=2,E9*(1-Вводные!$B$20)*Вводные!$B$19,0) | F10: =-IF(Вводные!$B$18=2,F9*(1-Вводные!$B$20)*Вводные!$B$19,0)
A11: − отчисления в РАО | B11: =-B9*Вводные!$B$26 | C11: =-C9*Вводные!$B$26 | D11: =-D9*Вводные!$B$26 | E11: =-E9*Вводные!$B$26 | F11: =-F9*Вводные!$B$26
A12: − УСН 6% с валового сбора | B12: =-B9*Вводные!$B$25 | C12: =-C9*Вводные!$B$25 | D12: =-D9*Вводные!$B$25 | E12: =-E9*Вводные!$B$25 | F12: =-F9*Вводные!$B$25
A13: СБОР ПОСЛЕ ВЫЧЕТОВ | B13: =SUM(B9:B12) | C13: =SUM(C9:C12) | D13: =SUM(D9:D12) | E13: =SUM(E9:E12) | F13: =SUM(F9:F12)
A14: − постоянные расходы (смета) | B14: =-Расходы!$E$58 | C14: =-Расходы!$E$58 | D14: =-Расходы!$E$58 | E14: =-Расходы!$E$58 | F14: =-Расходы!$E$58
A15: − переменные расходы на гостей | B15: =-B6*Вводные!$B$41 | C15: =-C6*Вводные!$B$41 | D15: =-D6*Вводные!$B$41 | E15: =-E6*Вводные!$B$41 | F15: =-F6*Вводные!$B$41
A16: + доп. доходы, участвующие в разделе | B16: =IF(Вводные!$B$38="Да",Билеты!$E$32*(1-Вводные!$B$25),0) | C16: =IF(Вводные!$B$38="Да",Билеты!$E$32*(1-Вводные!$B$25),0) | D16: =IF(Вводные!$B$38="Да",Билеты!$E$32*(1-Вводные!$B$25),0) | E16: =IF(Вводные!$B$38="Да",Билеты!$E$32*(1-Вводные!$B$25),0) | F16: =IF(Вводные!$B$38="Да",Билеты!$E$32*(1-Вводные!$B$25),0)
A17: ПРИБЫЛЬ К РАЗДЕЛУ | B17: =SUM(B13:B16) | C17: =SUM(C13:C16) | D17: =SUM(D13:D16) | E17: =SUM(E13:E16) | F17: =SUM(F13:F16) | G17: Именно эта строка делится с площадкой пополам
A18: доля площадки | B18: =IF(B17>=0,B17*Вводные!$B$36,IF(Вводные!$B$37="Да",B17*Вводные!$B$36,0)) | C18: =IF(C17>=0,C17*Вводные!$B$36,IF(Вводные!$B$37="Да",C17*Вводные!$B$36,0)) | D18: =IF(D17>=0,D17*Вводные!$B$36,IF(Вводные!$B$37="Да",D17*Вводные!$B$36,0)) | E18: =IF(E17>=0,E17*Вводные!$B$36,IF(Вводные!$B$37="Да",E17*Вводные!$B$36,0)) | F18: =IF(F17>=0,F17*Вводные!$B$36,IF(Вводные!$B$37="Да",F17*Вводные!$B$36,0)) | G18: При убытке площадка не участвует, если в договоре не сказано иное
A19: доля организатора (выплата по договору) | B19: =B17-B18 | C19: =C17-C18 | D19: =D17-D18 | E19: =E17-E18 | F19: =F17-F18
A20: − налог и комиссии с выплаты (8%) | B20: =-MAX(0,B19)*Вводные!$B$32 | C20: =-MAX(0,C19)*Вводные!$B$32 | D20: =-MAX(0,D19)*Вводные!$B$32 | E20: =-MAX(0,E19)*Вводные!$B$32 | F20: =-MAX(0,F19)*Вводные!$B$32
A21: Чистый доход от билетов | B21: =B19+B20 | C21: =C19+C20 | D21: =D19+D20 | E21: =E19+E20 | F21: =F19+F20
A22: + доп. доходы вне раздела (за вычетом 8%) | B22: =IF(Вводные!$B$38="Да",0,Билеты!$E$32)*(1-Вводные!$B$32) | C22: =IF(Вводные!$B$38="Да",0,Билеты!$E$32)*(1-Вводные!$B$32) | D22: =IF(Вводные!$B$38="Да",0,Билеты!$E$32)*(1-Вводные!$B$32) | E22: =IF(Вводные!$B$38="Да",0,Билеты!$E$32)*(1-Вводные!$B$32) | F22: =IF(Вводные!$B$38="Да",0,Билеты!$E$32)*(1-Вводные!$B$32)
A23: ИТОГО ЧИСТЫЙ ДОХОД ОРГАНИЗАТОРА | B23: =B21+B22 | C23: =C21+C22 | D23: =D21+D22 | E23: =E21+E22 | F23: =F21+F22 | G23: Деньги, которые реально останутся у вас после всех налогов
A24: Рентабельность к валовому сбору, % | B24: =IFERROR(B23/B9,0) | C24: =IFERROR(C23/C9,0) | D24: =IFERROR(D23/D9,0) | E24: =IFERROR(E23/E9,0) | F24: =IFERROR(F23/F9,0)
A25: Отклонение от базового сценария, ₽ | B25: =B23-$C$23 | C25: =C23-$C$23 | D25: =D23-$C$23 | E25: =E23-$C$23 | F25: =F23-$C$23 | G25: Цена риска: разброс между сценариями

Sheet Чувствительность
A1: ЧУВСТВИТЕЛЬНОСТЬ: ЦЕНА ПРОТИВ ЗАПОЛНЯЕМОСТИ
A2: Что будет с вашим чистым доходом при разной средней цене билета и разной заполняемости зала. Зелёное — прибыль, красное — убыток.
A4: ПРИБЫЛЬ К РАЗДЕЛУ С ПЛОЩАДКОЙ (до сплита и налога уровня 2), ₽
A5: Заполняемость \ Средняя цена | B5: 1500 | C5: 2000 | D5: 2500 | E5: 3000 | F5: 3500 | G5: 4000 | H5: 4500
A6: 0.3 | B6: =((Вводные!$B$12*$A6*Билеты!$B$23)*B$5)-IF(Вводные!$B$18=2,((Вводные!$B$12*$A6*Билеты!$B$23)*B$5)*(1-Вводные!$B$20)*Вводные!$B$19,0)-((Вводные!$B$12*$A6*Билеты!$B$23)*B$5)*Вводные!$B$26-((Вводные!$B$12*$A6*Билеты!$B$23)*B$5)*Вводные!$B$25-(Вводные!$B$12*$A6)*Вводные!$B$41-Расходы!$E$58+IF(Вводные!$B$38="Да",Билеты!$E$32*(1-Вводные!$B$25),0) | C6: =((Вводные!$B$12*$A6*Билеты!$B$23)*C$5)-IF(Вводные!$B$18=2,((Вводные!$B$12*$A6*Билеты!$B$23)*C$5)*(1-Вводные!$B$20)*Вводные!$B$19,0)-((Вводные!$B$12*$A6*Билеты!$B$23)*C$5)*Вводные!$B$26-((Вводные!$B$12*$A6*Билеты!$B$23)*C$5)*Вводные!$B$25-(Вводные!$B$12*$A6)*Вводные!$B$41-Расходы!$E$58+IF(Вводные!$B$38="Да",Билеты!$E$32*(1-Вводные!$B$25),0) | D6: =((Вводные!$B$12*$A6*Билеты!$B$23)*D$5)-IF(Вводные!$B$18=2,((Вводные!$B$12*$A6*Билеты!$B$23)*D$5)*(1-Вводные!$B$20)*Вводные!$B$19,0)-((Вводные!$B$12*$A6*Билеты!$B$23)*D$5)*Вводные!$B$26-((Вводные!$B$12*$A6*Билеты!$B$23)*D$5)*Вводные!$B$25-(Вводные!$B$12*$A6)*Вводные!$B$41-Расходы!$E$58+IF(Вводные!$B$38="Да",Билеты!$E$32*(1-Вводные!$B$25),0) | E6: =((Вводные!$B$12*$A6*Билеты!$B$23)*E$5)-IF(Вводные!$B$18=2,((Вводные!$B$12*$A6*Билеты!$B$23)*E$5)*(1-Вводные!$B$20)*Вводные!$B$19,0)-((Вводные!$B$12*$A6*Билеты!$B$23)*E$5)*Вводные!$B$26-((Вводные!$B$12*$A6*Билеты!$B$23)*E$5)*Вводные!$B$25-(Вводные!$B$12*$A6)*Вводные!$B$41-Расходы!$E$58+IF(Вводные!$B$38="Да",Билеты!$E$32*(1-Вводные!$B$25),0) | F6: =((Вводные!$B$12*$A6*Билеты!$B$23)*F$5)-IF(Вводные!$B$18=2,((Вводные!$B$12*$A6*Билеты!$B$23)*F$5)*(1-Вводные!$B$20)*Вводные!$B$19,0)-((Вводные!$B$12*$A6*Билеты!$B$23)*F$5)*Вводные!$B$26-((Вводные!$B$12*$A6*Билеты!$B$23)*F$5)*Вводные!$B$25-(Вводные!$B$12*$A6)*Вводные!$B$41-Расходы!$E$58+IF(Вводные!$B$38="Да",Билеты!$E$32*(1-Вводные!$B$25),0) | G6: =((Вводные!$B$12*$A6*Билеты!$B$23)*G$5)-IF(Вводные!$B$18=2,((Вводные!$B$12*$A6*Билеты!$B$23)*G$5)*(1-Вводные!$B$20)*Вводные!$B$19,0)-((Вводные!$B$12*$A6*Билеты!$B$23)*G$5)*Вводные!$B$26-((Вводные!$B$12*$A6*Билеты!$B$23)*G$5)*Вводные!$B$25-(Вводные!$B$12*$A6)*Вводные!$B$41-Расходы!$E$58+IF(Вводные!$B$38="Да",Билеты!$E$32*(1-Вводные!$B$25),0) | H6: =((Вводные!$B$12*$A6*Билеты!$B$23)*H$5)-IF(Вводные!$B$18=2,((Вводные!$B$12*$A6*Билеты!$B$23)*H$5)*(1-Вводные!$B$20)*Вводные!$B$19,0)-((Вводные!$B$12*$A6*Билеты!$B$23)*H$5)*Вводные!$B$26-((Вводные!$B$12*$A6*Билеты!$B$23)*H$5)*Вводные!$B$25-(Вводные!$B$12*$A6)*Вводные!$B$41-Расходы!$E$58+IF(Вводные!$B$38="Да",Билеты!$E$32*(1-Вводные!$B$25),0)
A7: 0.4 | B7: =((Вводные!$B$12*$A7*Билеты!$B$23)*B$5)-IF(Вводные!$B$18=2,((Вводные!$B$12*$A7*Билеты!$B$23)*B$5)*(1-Вводные!$B$20)*Вводные!$B$19,0)-((Вводные!$B$12*$A7*Билеты!$B$23)*B$5)*Вводные!$B$26-((Вводные!$B$12*$A7*Билеты!$B$23)*B$5)*Вводные!$B$25-(Вводные!$B$12*$A7)*Вводные!$B$41-Расходы!$E$58+IF(Вводные!$B$38="Да",Билеты!$E$32*(1-Вводные!$B$25),0) | C7: =((Вводные!$B$12*$A7*Билеты!$B$23)*C$5)-IF(Вводные!$B$18=2,((Вводные!$B$12*$A7*Билеты!$B$23)*C$5)*(1-Вводные!$B$20)*Вводные!$B$19,0)-((Вводные!$B$12*$A7*Билеты!$B$23)*C$5)*Вводные!$B$26-((Вводные!$B$12*$A7*Билеты!$B$23)*C$5)*Вводные!$B$25-(Вводные!$B$12*$A7)*Вводные!$B$41-Расходы!$E$58+IF(Вводные!$B$38="Да",Билеты!$E$32*(1-Вводные!$B$25),0) | D7: =((Вводные!$B$12*$A7*Билеты!$B$23)*D$5)-IF(Вводные!$B$18=2,((Вводные!$B$12*$A7*Билеты!$B$23)*D$5)*(1-Вводные!$B$20)*Вводные!$B$19,0)-((Вводные!$B$12*$A7*Билеты!$B$23)*D$5)*Вводные!$B$26-((Вводные!$B$12*$A7*Билеты!$B$23)*D$5)*Вводные!$B$25-(Вводные!$B$12*$A7)*Вводные!$B$41-Расходы!$E$58+IF(Вводные!$B$38="Да",Билеты!$E$32*(1-Вводные!$B$25),0) | E7: =((Вводные!$B$12*$A7*Билеты!$B$23)*E$5)-IF(Вводные!$B$18=2,((Вводные!$B$12*$A7*Билеты!$B$23)*E$5)*(1-Вводные!$B$20)*Вводные!$B$19,0)-((Вводные!$B$12*$A7*Билеты!$B$23)*E$5)*Вводные!$B$26-((Вводные!$B$12*$A7*Билеты!$B$23)*E$5)*Вводные!$B$25-(Вводные!$B$12*$A7)*Вводные!$B$41-Расходы!$E$58+IF(Вводные!$B$38="Да",Билеты!$E$32*(1-Вводные!$B$25),0) | F7: =((Вводные!$B$12*$A7*Билеты!$B$23)*F$5)-IF(Вводные!$B$18=2,((Вводные!$B$12*$A7*Билеты!$B$23)*F$5)*(1-Вводные!$B$20)*Вводные!$B$19,0)-((Вводные!$B$12*$A7*Билеты!$B$23)*F$5)*Вводные!$B$26-((Вводные!$B$12*$A7*Билеты!$B$23)*F$5)*Вводные!$B$25-(Вводные!$B$12*$A7)*Вводные!$B$41-Расходы!$E$58+IF(Вводные!$B$38="Да",Билеты!$E$32*(1-Вводные!$B$25),0) | G7: =((Вводные!$B$12*$A7*Билеты!$B$23)*G$5)-IF(Вводные!$B$18=2,((Вводные!$B$12*$A7*Билеты!$B$23)*G$5)*(1-Вводные!$B$20)*Вводные!$B$19,0)-((Вводные!$B$12*$A7*Билеты!$B$23)*G$5)*Вводные!$B$26-((Вводные!$B$12*$A7*Билеты!$B$23)*G$5)*Вводные!$B$25-(Вводные!$B$12*$A7)*Вводные!$B$41-Расходы!$E$58+IF(Вводные!$B$38="Да",Билеты!$E$32*(1-Вводные!$B$25),0) | H7: =((Вводные!$B$12*$A7*Билеты!$B$23)*H$5)-IF(Вводные!$B$18=2,((Вводные!$B$12*$A7*Билеты!$B$23)*H$5)*(1-Вводные!$B$20)*Вводные!$B$19,0)-((Вводные!$B$12*$A7*Билеты!$B$23)*H$5)*Вводные!$B$26-((Вводные!$B$12*$A7*Билеты!$B$23)*H$5)*Вводные!$B$25-(Вводные!$B$12*$A7)*Вводные!$B$41-Расходы!$E$58+IF(Вводные!$B$38="Да",Билеты!$E$32*(1-Вводные!$B$25),0)
A8: 0.5 | B8: =((Вводные!$B$12*$A8*Билеты!$B$23)*B$5)-IF(Вводные!$B$18=2,((Вводные!$B$12*$A8*Билеты!$B$23)*B$5)*(1-Вводные!$B$20)*Вводные!$B$19,0)-((Вводные!$B$12*$A8*Билеты!$B$23)*B$5)*Вводные!$B$26-((Вводные!$B$12*$A8*Билеты!$B$23)*B$5)*Вводные!$B$25-(Вводные!$B$12*$A8)*Вводные!$B$41-Расходы!$E$58+IF(Вводные!$B$38="Да",Билеты!$E$32*(1-Вводные!$B$25),0) | C8: =((Вводные!$B$12*$A8*Билеты!$B$23)*C$5)-IF(Вводные!$B$18=2,((Вводные!$B$12*$A8*Билеты!$B$23)*C$5)*(1-Вводные!$B$20)*Вводные!$B$19,0)-((Вводные!$B$12*$A8*Билеты!$B$23)*C$5)*Вводные!$B$26-((Вводные!$B$12*$A8*Билеты!$B$23)*C$5)*Вводные!$B$25-(Вводные!$B$12*$A8)*Вводные!$B$41-Расходы!$E$58+IF(Вводные!$B$38="Да",Билеты!$E$32*(1-Вводные!$B$25),0) | D8: =((Вводные!$B$12*$A8*Билеты!$B$23)*D$5)-IF(Вводные!$B$18=2,((Вводные!$B$12*$A8*Билеты!$B$23)*D$5)*(1-Вводные!$B$20)*Вводные!$B$19,0)-((Вводные!$B$12*$A8*Билеты!$B$23)*D$5)*Вводные!$B$26-((Вводные!$B$12*$A8*Билеты!$B$23)*D$5)*Вводные!$B$25-(Вводные!$B$12*$A8)*Вводные!$B$41-Расходы!$E$58+IF(Вводные!$B$38="Да",Билеты!$E$32*(1-Вводные!$B$25),0) | E8: =((Вводные!$B$12*$A8*Билеты!$B$23)*E$5)-IF(Вводные!$B$18=2,((Вводные!$B$12*$A8*Билеты!$B$23)*E$5)*(1-Вводные!$B$20)*Вводные!$B$19,0)-((Вводные!$B$12*$A8*Билеты!$B$23)*E$5)*Вводные!$B$26-((Вводные!$B$12*$A8*Билеты!$B$23)*E$5)*Вводные!$B$25-(Вводные!$B$12*$A8)*Вводные!$B$41-Расходы!$E$58+IF(Вводные!$B$38="Да",Билеты!$E$32*(1-Вводные!$B$25),0) | F8: =((Вводные!$B$12*$A8*Билеты!$B$23)*F$5)-IF(Вводные!$B$18=2,((Вводные!$B$12*$A8*Билеты!$B$23)*F$5)*(1-Вводные!$B$20)*Вводные!$B$19,0)-((Вводные!$B$12*$A8*Билеты!$B$23)*F$5)*Вводные!$B$26-((Вводные!$B$12*$A8*Билеты!$B$23)*F$5)*Вводные!$B$25-(Вводные!$B$12*$A8)*Вводные!$B$41-Расходы!$E$58+IF(Вводные!$B$38="Да",Билеты!$E$32*(1-Вводные!$B$25),0) | G8: =((Вводные!$B$12*$A8*Билеты!$B$23)*G$5)-IF(Вводные!$B$18=2,((Вводные!$B$12*$A8*Билеты!$B$23)*G$5)*(1-Вводные!$B$20)*Вводные!$B$19,0)-((Вводные!$B$12*$A8*Билеты!$B$23)*G$5)*Вводные!$B$26-((Вводные!$B$12*$A8*Билеты!$B$23)*G$5)*Вводные!$B$25-(Вводные!$B$12*$A8)*Вводные!$B$41-Расходы!$E$58+IF(Вводные!$B$38="Да",Билеты!$E$32*(1-Вводные!$B$25),0) | H8: =((Вводные!$B$12*$A8*Билеты!$B$23)*H$5)-IF(Вводные!$B$18=2,((Вводные!$B$12*$A8*Билеты!$B$23)*H$5)*(1-Вводные!$B$20)*Вводные!$B$19,0)-((Вводные!$B$12*$A8*Билеты!$B$23)*H$5)*Вводные!$B$26-((Вводные!$B$12*$A8*Билеты!$B$23)*H$5)*Вводные!$B$25-(Вводные!$B$12*$A8)*Вводные!$B$41-Расходы!$E$58+IF(Вводные!$B$38="Да",Билеты!$E$32*(1-Вводные!$B$25),0)
A9: 0.6 | B9: =((Вводные!$B$12*$A9*Билеты!$B$23)*B$5)-IF(Вводные!$B$18=2,((Вводные!$B$12*$A9*Билеты!$B$23)*B$5)*(1-Вводные!$B$20)*Вводные!$B$19,0)-((Вводные!$B$12*$A9*Билеты!$B$23)*B$5)*Вводные!$B$26-((Вводные!$B$12*$A9*Билеты!$B$23)*B$5)*Вводные!$B$25-(Вводные!$B$12*$A9)*Вводные!$B$41-Расходы!$E$58+IF(Вводные!$B$38="Да",Билеты!$E$32*(1-Вводные!$B$25),0) | C9: =((Вводные!$B$12*$A9*Билеты!$B$23)*C$5)-IF(Вводные!$B$18=2,((Вводные!$B$12*$A9*Билеты!$B$23)*C$5)*(1-Вводные!$B$20)*Вводные!$B$19,0)-((Вводные!$B$12*$A9*Билеты!$B$23)*C$5)*Вводные!$B$26-((Вводные!$B$12*$A9*Билеты!$B$23)*C$5)*Вводные!$B$25-(Вводные!$B$12*$A9)*Вводные!$B$41-Расходы!$E$58+IF(Вводные!$B$38="Да",Билеты!$E$32*(1-Вводные!$B$25),0) | D9: =((Вводные!$B$12*$A9*Билеты!$B$23)*D$5)-IF(Вводные!$B$18=2,((Вводные!$B$12*$A9*Билеты!$B$23)*D$5)*(1-Вводные!$B$20)*Вводные!$B$19,0)-((Вводные!$B$12*$A9*Билеты!$B$23)*D$5)*Вводные!$B$26-((Вводные!$B$12*$A9*Билеты!$B$23)*D$5)*Вводные!$B$25-(Вводные!$B$12*$A9)*Вводные!$B$41-Расходы!$E$58+IF(Вводные!$B$38="Да",Билеты!$E$32*(1-Вводные!$B$25),0) | E9: =((Вводные!$B$12*$A9*Билеты!$B$23)*E$5)-IF(Вводные!$B$18=2,((Вводные!$B$12*$A9*Билеты!$B$23)*E$5)*(1-Вводные!$B$20)*Вводные!$B$19,0)-((Вводные!$B$12*$A9*Билеты!$B$23)*E$5)*Вводные!$B$26-((Вводные!$B$12*$A9*Билеты!$B$23)*E$5)*Вводные!$B$25-(Вводные!$B$12*$A9)*Вводные!$B$41-Расходы!$E$58+IF(Вводные!$B$38="Да",Билеты!$E$32*(1-Вводные!$B$25),0) | F9: =((Вводные!$B$12*$A9*Билеты!$B$23)*F$5)-IF(Вводные!$B$18=2,((Вводные!$B$12*$A9*Билеты!$B$23)*F$5)*(1-Вводные!$B$20)*Вводные!$B$19,0)-((Вводные!$B$12*$A9*Билеты!$B$23)*F$5)*Вводные!$B$26-((Вводные!$B$12*$A9*Билеты!$B$23)*F$5)*Вводные!$B$25-(Вводные!$B$12*$A9)*Вводные!$B$41-Расходы!$E$58+IF(Вводные!$B$38="Да",Билеты!$E$32*(1-Вводные!$B$25),0) | G9: =((Вводные!$B$12*$A9*Билеты!$B$23)*G$5)-IF(Вводные!$B$18=2,((Вводные!$B$12*$A9*Билеты!$B$23)*G$5)*(1-Вводные!$B$20)*Вводные!$B$19,0)-((Вводные!$B$12*$A9*Билеты!$B$23)*G$5)*Вводные!$B$26-((Вводные!$B$12*$A9*Билеты!$B$23)*G$5)*Вводные!$B$25-(Вводные!$B$12*$A9)*Вводные!$B$41-Расходы!$E$58+IF(Вводные!$B$38="Да",Билеты!$E$32*(1-Вводные!$B$25),0) | H9: =((Вводные!$B$12*$A9*Билеты!$B$23)*H$5)-IF(Вводные!$B$18=2,((Вводные!$B$12*$A9*Билеты!$B$23)*H$5)*(1-Вводные!$B$20)*Вводные!$B$19,0)-((Вводные!$B$12*$A9*Билеты!$B$23)*H$5)*Вводные!$B$26-((Вводные!$B$12*$A9*Билеты!$B$23)*H$5)*Вводные!$B$25-(Вводные!$B$12*$A9)*Вводные!$B$41-Расходы!$E$58+IF(Вводные!$B$38="Да",Билеты!$E$32*(1-Вводные!$B$25),0)
A10: 0.7 | B10: =((Вводные!$B$12*$A10*Билеты!$B$23)*B$5)-IF(Вводные!$B$18=2,((Вводные!$B$12*$A10*Билеты!$B$23)*B$5)*(1-Вводные!$B$20)*Вводные!$B$19,0)-((Вводные!$B$12*$A10*Билеты!$B$23)*B$5)*Вводные!$B$26-((Вводные!$B$12*$A10*Билеты!$B$23)*B$5)*Вводные!$B$25-(Вводные!$B$12*$A10)*Вводные!$B$41-Расходы!$E$58+IF(Вводные!$B$38="Да",Билеты!$E$32*(1-Вводные!$B$25),0) | C10: =((Вводные!$B$12*$A10*Билеты!$B$23)*C$5)-IF(Вводные!$B$18=2,((Вводные!$B$12*$A10*Билеты!$B$23)*C$5)*(1-Вводные!$B$20)*Вводные!$B$19,0)-((Вводные!$B$12*$A10*Билеты!$B$23)*C$5)*Вводные!$B$26-((Вводные!$B$12*$A10*Билеты!$B$23)*C$5)*Вводные!$B$25-(Вводные!$B$12*$A10)*Вводные!$B$41-Расходы!$E$58+IF(Вводные!$B$38="Да",Билеты!$E$32*(1-Вводные!$B$25),0) | D10: =((Вводные!$B$12*$A10*Билеты!$B$23)*D$5)-IF(Вводные!$B$18=2,((Вводные!$B$12*$A10*Билеты!$B$23)*D$5)*(1-Вводные!$B$20)*Вводные!$B$19,0)-((Вводные!$B$12*$A10*Билеты!$B$23)*D$5)*Вводные!$B$26-((Вводные!$B$12*$A10*Билеты!$B$23)*D$5)*Вводные!$B$25-(Вводные!$B$12*$A10)*Вводные!$B$41-Расходы!$E$58+IF(Вводные!$B$38="Да",Билеты!$E$32*(1-Вводные!$B$25),0) | E10: =((Вводные!$B$12*$A10*Билеты!$B$23)*E$5)-IF(Вводные!$B$18=2,((Вводные!$B$12*$A10*Билеты!$B$23)*E$5)*(1-Вводные!$B$20)*Вводные!$B$19,0)-((Вводные!$B$12*$A10*Билеты!$B$23)*E$5)*Вводные!$B$26-((Вводные!$B$12*$A10*Билеты!$B$23)*E$5)*Вводные!$B$25-(Вводные!$B$12*$A10)*Вводные!$B$41-Расходы!$E$58+IF(Вводные!$B$38="Да",Билеты!$E$32*(1-Вводные!$B$25),0) | F10: =((Вводные!$B$12*$A10*Билеты!$B$23)*F$5)-IF(Вводные!$B$18=2,((Вводные!$B$12*$A10*Билеты!$B$23)*F$5)*(1-Вводные!$B$20)*Вводные!$B$19,0)-((Вводные!$B$12*$A10*Билеты!$B$23)*F$5)*Вводные!$B$26-((Вводные!$B$12*$A10*Билеты!$B$23)*F$5)*Вводные!$B$25-(Вводные!$B$12*$A10)*Вводные!$B$41-Расходы!$E$58+IF(Вводные!$B$38="Да",Билеты!$E$32*(1-Вводные!$B$25),0) | G10: =((Вводные!$B$12*$A10*Билеты!$B$23)*G$5)-IF(Вводные!$B$18=2,((Вводные!$B$12*$A10*Билеты!$B$23)*G$5)*(1-Вводные!$B$20)*Вводные!$B$19,0)-((Вводные!$B$12*$A10*Билеты!$B$23)*G$5)*Вводные!$B$26-((Вводные!$B$12*$A10*Билеты!$B$23)*G$5)*Вводные!$B$25-(Вводные!$B$12*$A10)*Вводные!$B$41-Расходы!$E$58+IF(Вводные!$B$38="Да",Билеты!$E$32*(1-Вводные!$B$25),0) | H10: =((Вводные!$B$12*$A10*Билеты!$B$23)*H$5)-IF(Вводные!$B$18=2,((Вводные!$B$12*$A10*Билеты!$B$23)*H$5)*(1-Вводные!$B$20)*Вводные!$B$19,0)-((Вводные!$B$12*$A10*Билеты!$B$23)*H$5)*Вводные!$B$26-((Вводные!$B$12*$A10*Билеты!$B$23)*H$5)*Вводные!$B$25-(Вводные!$B$12*$A10)*Вводные!$B$41-Расходы!$E$58+IF(Вводные!$B$38="Да",Билеты!$E$32*(1-Вводные!$B$25),0)
A11: 0.8 | B11: =((Вводные!$B$12*$A11*Билеты!$B$23)*B$5)-IF(Вводные!$B$18=2,((Вводные!$B$12*$A11*Билеты!$B$23)*B$5)*(1-Вводные!$B$20)*Вводные!$B$19,0)-((Вводные!$B$12*$A11*Билеты!$B$23)*B$5)*Вводные!$B$26-((Вводные!$B$12*$A11*Билеты!$B$23)*B$5)*Вводные!$B$25-(Вводные!$B$12*$A11)*Вводные!$B$41-Расходы!$E$58+IF(Вводные!$B$38="Да",Билеты!$E$32*(1-Вводные!$B$25),0) | C11: =((Вводные!$B$12*$A11*Билеты!$B$23)*C$5)-IF(Вводные!$B$18=2,((Вводные!$B$12*$A11*Билеты!$B$23)*C$5)*(1-Вводные!$B$20)*Вводные!$B$19,0)-((Вводные!$B$12*$A11*Билеты!$B$23)*C$5)*Вводные!$B$26-((Вводные!$B$12*$A11*Билеты!$B$23)*C$5)*Вводные!$B$25-(Вводные!$B$12*$A11)*Вводные!$B$41-Расходы!$E$58+IF(Вводные!$B$38="Да",Билеты!$E$32*(1-Вводные!$B$25),0) | D11: =((Вводные!$B$12*$A11*Билеты!$B$23)*D$5)-IF(Вводные!$B$18=2,((Вводные!$B$12*$A11*Билеты!$B$23)*D$5)*(1-Вводные!$B$20)*Вводные!$B$19,0)-((Вводные!$B$12*$A11*Билеты!$B$23)*D$5)*Вводные!$B$26-((Вводные!$B$12*$A11*Билеты!$B$23)*D$5)*Вводные!$B$25-(Вводные!$B$12*$A11)*Вводные!$B$41-Расходы!$E$58+IF(Вводные!$B$38="Да",Билеты!$E$32*(1-Вводные!$B$25),0) | E11: =((Вводные!$B$12*$A11*Билеты!$B$23)*E$5)-IF(Вводные!$B$18=2,((Вводные!$B$12*$A11*Билеты!$B$23)*E$5)*(1-Вводные!$B$20)*Вводные!$B$19,0)-((Вводные!$B$12*$A11*Билеты!$B$23)*E$5)*Вводные!$B$26-((Вводные!$B$12*$A11*Билеты!$B$23)*E$5)*Вводные!$B$25-(Вводные!$B$12*$A11)*Вводные!$B$41-Расходы!$E$58+IF(Вводные!$B$38="Да",Билеты!$E$32*(1-Вводные!$B$25),0) | F11: =((Вводные!$B$12*$A11*Билеты!$B$23)*F$5)-IF(Вводные!$B$18=2,((Вводные!$B$12*$A11*Билеты!$B$23)*F$5)*(1-Вводные!$B$20)*Вводные!$B$19,0)-((Вводные!$B$12*$A11*Билеты!$B$23)*F$5)*Вводные!$B$26-((Вводные!$B$12*$A11*Билеты!$B$23)*F$5)*Вводные!$B$25-(Вводные!$B$12*$A11)*Вводные!$B$41-Расходы!$E$58+IF(Вводные!$B$38="Да",Билеты!$E$32*(1-Вводные!$B$25),0) | G11: =((Вводные!$B$12*$A11*Билеты!$B$23)*G$5)-IF(Вводные!$B$18=2,((Вводные!$B$12*$A11*Билеты!$B$23)*G$5)*(1-Вводные!$B$20)*Вводные!$B$19,0)-((Вводные!$B$12*$A11*Билеты!$B$23)*G$5)*Вводные!$B$26-((Вводные!$B$12*$A11*Билеты!$B$23)*G$5)*Вводные!$B$25-(Вводные!$B$12*$A11)*Вводные!$B$41-Расходы!$E$58+IF(Вводные!$B$38="Да",Билеты!$E$32*(1-Вводные!$B$25),0) | H11: =((Вводные!$B$12*$A11*Билеты!$B$23)*H$5)-IF(Вводные!$B$18=2,((Вводные!$B$12*$A11*Билеты!$B$23)*H$5)*(1-Вводные!$B$20)*Вводные!$B$19,0)-((Вводные!$B$12*$A11*Билеты!$B$23)*H$5)*Вводные!$B$26-((Вводные!$B$12*$A11*Билеты!$B$23)*H$5)*Вводные!$B$25-(Вводные!$B$12*$A11)*Вводные!$B$41-Расходы!$E$58+IF(Вводные!$B$38="Да",Билеты!$E$32*(1-Вводные!$B$25),0)
A12: 0.9 | B12: =((Вводные!$B$12*$A12*Билеты!$B$23)*B$5)-IF(Вводные!$B$18=2,((Вводные!$B$12*$A12*Билеты!$B$23)*B$5)*(1-Вводные!$B$20)*Вводные!$B$19,0)-((Вводные!$B$12*$A12*Билеты!$B$23)*B$5)*Вводные!$B$26-((Вводные!$B$12*$A12*Билеты!$B$23)*B$5)*Вводные!$B$25-(Вводные!$B$12*$A12)*Вводные!$B$41-Расходы!$E$58+IF(Вводные!$B$38="Да",Билеты!$E$32*(1-Вводные!$B$25),0) | C12: =((Вводные!$B$12*$A12*Билеты!$B$23)*C$5)-IF(Вводные!$B$18=2,((Вводные!$B$12*$A12*Билеты!$B$23)*C$5)*(1-Вводные!$B$20)*Вводные!$B$19,0)-((Вводные!$B$12*$A12*Билеты!$B$23)*C$5)*Вводные!$B$26-((Вводные!$B$12*$A12*Билеты!$B$23)*C$5)*Вводные!$B$25-(Вводные!$B$12*$A12)*Вводные!$B$41-Расходы!$E$58+IF(Вводные!$B$38="Да",Билеты!$E$32*(1-Вводные!$B$25),0) | D12: =((Вводные!$B$12*$A12*Билеты!$B$23)*D$5)-IF(Вводные!$B$18=2,((Вводные!$B$12*$A12*Билеты!$B$23)*D$5)*(1-Вводные!$B$20)*Вводные!$B$19,0)-((Вводные!$B$12*$A12*Билеты!$B$23)*D$5)*Вводные!$B$26-((Вводные!$B$12*$A12*Билеты!$B$23)*D$5)*Вводные!$B$25-(Вводные!$B$12*$A12)*Вводные!$B$41-Расходы!$E$58+IF(Вводные!$B$38="Да",Билеты!$E$32*(1-Вводные!$B$25),0) | E12: =((Вводные!$B$12*$A12*Билеты!$B$23)*E$5)-IF(Вводные!$B$18=2,((Вводные!$B$12*$A12*Билеты!$B$23)*E$5)*(1-Вводные!$B$20)*Вводные!$B$19,0)-((Вводные!$B$12*$A12*Билеты!$B$23)*E$5)*Вводные!$B$26-((Вводные!$B$12*$A12*Билеты!$B$23)*E$5)*Вводные!$B$25-(Вводные!$B$12*$A12)*Вводные!$B$41-Расходы!$E$58+IF(Вводные!$B$38="Да",Билеты!$E$32*(1-Вводные!$B$25),0) | F12: =((Вводные!$B$12*$A12*Билеты!$B$23)*F$5)-IF(Вводные!$B$18=2,((Вводные!$B$12*$A12*Билеты!$B$23)*F$5)*(1-Вводные!$B$20)*Вводные!$B$19,0)-((Вводные!$B$12*$A12*Билеты!$B$23)*F$5)*Вводные!$B$26-((Вводные!$B$12*$A12*Билеты!$B$23)*F$5)*Вводные!$B$25-(Вводные!$B$12*$A12)*Вводные!$B$41-Расходы!$E$58+IF(Вводные!$B$38="Да",Билеты!$E$32*(1-Вводные!$B$25),0) | G12: =((Вводные!$B$12*$A12*Билеты!$B$23)*G$5)-IF(Вводные!$B$18=2,((Вводные!$B$12*$A12*Билеты!$B$23)*G$5)*(1-Вводные!$B$20)*Вводные!$B$19,0)-((Вводные!$B$12*$A12*Билеты!$B$23)*G$5)*Вводные!$B$26-((Вводные!$B$12*$A12*Билеты!$B$23)*G$5)*Вводные!$B$25-(Вводные!$B$12*$A12)*Вводные!$B$41-Расходы!$E$58+IF(Вводные!$B$38="Да",Билеты!$E$32*(1-Вводные!$B$25),0) | H12: =((Вводные!$B$12*$A12*Билеты!$B$23)*H$5)-IF(Вводные!$B$18=2,((Вводные!$B$12*$A12*Билеты!$B$23)*H$5)*(1-Вводные!$B$20)*Вводные!$B$19,0)-((Вводные!$B$12*$A12*Билеты!$B$23)*H$5)*Вводные!$B$26-((Вводные!$B$12*$A12*Билеты!$B$23)*H$5)*Вводные!$B$25-(Вводные!$B$12*$A12)*Вводные!$B$41-Расходы!$E$58+IF(Вводные!$B$38="Да",Билеты!$E$32*(1-Вводные!$B$25),0)
A13: 1 | B13: =((Вводные!$B$12*$A13*Билеты!$B$23)*B$5)-IF(Вводные!$B$18=2,((Вводные!$B$12*$A13*Билеты!$B$23)*B$5)*(1-Вводные!$B$20)*Вводные!$B$19,0)-((Вводные!$B$12*$A13*Билеты!$B$23)*B$5)*Вводные!$B$26-((Вводные!$B$12*$A13*Билеты!$B$23)*B$5)*Вводные!$B$25-(Вводные!$B$12*$A13)*Вводные!$B$41-Расходы!$E$58+IF(Вводные!$B$38="Да",Билеты!$E$32*(1-Вводные!$B$25),0) | C13: =((Вводные!$B$12*$A13*Билеты!$B$23)*C$5)-IF(Вводные!$B$18=2,((Вводные!$B$12*$A13*Билеты!$B$23)*C$5)*(1-Вводные!$B$20)*Вводные!$B$19,0)-((Вводные!$B$12*$A13*Билеты!$B$23)*C$5)*Вводные!$B$26-((Вводные!$B$12*$A13*Билеты!$B$23)*C$5)*Вводные!$B$25-(Вводные!$B$12*$A13)*Вводные!$B$41-Расходы!$E$58+IF(Вводные!$B$38="Да",Билеты!$E$32*(1-Вводные!$B$25),0) | D13: =((Вводные!$B$12*$A13*Билеты!$B$23)*D$5)-IF(Вводные!$B$18=2,((Вводные!$B$12*$A13*Билеты!$B$23)*D$5)*(1-Вводные!$B$20)*Вводные!$B$19,0)-((Вводные!$B$12*$A13*Билеты!$B$23)*D$5)*Вводные!$B$26-((Вводные!$B$12*$A13*Билеты!$B$23)*D$5)*Вводные!$B$25-(Вводные!$B$12*$A13)*Вводные!$B$41-Расходы!$E$58+IF(Вводные!$B$38="Да",Билеты!$E$32*(1-Вводные!$B$25),0) | E13: =((Вводные!$B$12*$A13*Билеты!$B$23)*E$5)-IF(Вводные!$B$18=2,((Вводные!$B$12*$A13*Билеты!$B$23)*E$5)*(1-Вводные!$B$20)*Вводные!$B$19,0)-((Вводные!$B$12*$A13*Билеты!$B$23)*E$5)*Вводные!$B$26-((Вводные!$B$12*$A13*Билеты!$B$23)*E$5)*Вводные!$B$25-(Вводные!$B$12*$A13)*Вводные!$B$41-Расходы!$E$58+IF(Вводные!$B$38="Да",Билеты!$E$32*(1-Вводные!$B$25),0) | F13: =((Вводные!$B$12*$A13*Билеты!$B$23)*F$5)-IF(Вводные!$B$18=2,((Вводные!$B$12*$A13*Билеты!$B$23)*F$5)*(1-Вводные!$B$20)*Вводные!$B$19,0)-((Вводные!$B$12*$A13*Билеты!$B$23)*F$5)*Вводные!$B$26-((Вводные!$B$12*$A13*Билеты!$B$23)*F$5)*Вводные!$B$25-(Вводные!$B$12*$A13)*Вводные!$B$41-Расходы!$E$58+IF(Вводные!$B$38="Да",Билеты!$E$32*(1-Вводные!$B$25),0) | G13: =((Вводные!$B$12*$A13*Билеты!$B$23)*G$5)-IF(Вводные!$B$18=2,((Вводные!$B$12*$A13*Билеты!$B$23)*G$5)*(1-Вводные!$B$20)*Вводные!$B$19,0)-((Вводные!$B$12*$A13*Билеты!$B$23)*G$5)*Вводные!$B$26-((Вводные!$B$12*$A13*Билеты!$B$23)*G$5)*Вводные!$B$25-(Вводные!$B$12*$A13)*Вводные!$B$41-Расходы!$E$58+IF(Вводные!$B$38="Да",Билеты!$E$32*(1-Вводные!$B$25),0) | H13: =((Вводные!$B$12*$A13*Билеты!$B$23)*H$5)-IF(Вводные!$B$18=2,((Вводные!$B$12*$A13*Билеты!$B$23)*H$5)*(1-Вводные!$B$20)*Вводные!$B$19,0)-((Вводные!$B$12*$A13*Билеты!$B$23)*H$5)*Вводные!$B$26-((Вводные!$B$12*$A13*Билеты!$B$23)*H$5)*Вводные!$B$25-(Вводные!$B$12*$A13)*Вводные!$B$41-Расходы!$E$58+IF(Вводные!$B$38="Да",Билеты!$E$32*(1-Вводные!$B$25),0)
A15: ИТОГО чистый доход организатора после раздела и всех налогов, ₽
A16: Заполняемость \ Средняя цена | B16: 1500 | C16: 2000 | D16: 2500 | E16: 3000 | F16: 3500 | G16: 4000 | H16: 4500
A17: 0.3 | B17: =IF(B6>=0,B6*Вводные!$B$35,IF(Вводные!$B$37="Да",B6*Вводные!$B$35,B6))-MAX(0,IF(B6>=0,B6*Вводные!$B$35,IF(Вводные!$B$37="Да",B6*Вводные!$B$35,B6)))*Вводные!$B$32+IF(Вводные!$B$38="Да",0,Билеты!$E$32)*(1-Вводные!$B$32) | C17: =IF(C6>=0,C6*Вводные!$B$35,IF(Вводные!$B$37="Да",C6*Вводные!$B$35,C6))-MAX(0,IF(C6>=0,C6*Вводные!$B$35,IF(Вводные!$B$37="Да",C6*Вводные!$B$35,C6)))*Вводные!$B$32+IF(Вводные!$B$38="Да",0,Билеты!$E$32)*(1-Вводные!$B$32) | D17: =IF(D6>=0,D6*Вводные!$B$35,IF(Вводные!$B$37="Да",D6*Вводные!$B$35,D6))-MAX(0,IF(D6>=0,D6*Вводные!$B$35,IF(Вводные!$B$37="Да",D6*Вводные!$B$35,D6)))*Вводные!$B$32+IF(Вводные!$B$38="Да",0,Билеты!$E$32)*(1-Вводные!$B$32) | E17: =IF(E6>=0,E6*Вводные!$B$35,IF(Вводные!$B$37="Да",E6*Вводные!$B$35,E6))-MAX(0,IF(E6>=0,E6*Вводные!$B$35,IF(Вводные!$B$37="Да",E6*Вводные!$B$35,E6)))*Вводные!$B$32+IF(Вводные!$B$38="Да",0,Билеты!$E$32)*(1-Вводные!$B$32) | F17: =IF(F6>=0,F6*Вводные!$B$35,IF(Вводные!$B$37="Да",F6*Вводные!$B$35,F6))-MAX(0,IF(F6>=0,F6*Вводные!$B$35,IF(Вводные!$B$37="Да",F6*Вводные!$B$35,F6)))*Вводные!$B$32+IF(Вводные!$B$38="Да",0,Билеты!$E$32)*(1-Вводные!$B$32) | G17: =IF(G6>=0,G6*Вводные!$B$35,IF(Вводные!$B$37="Да",G6*Вводные!$B$35,G6))-MAX(0,IF(G6>=0,G6*Вводные!$B$35,IF(Вводные!$B$37="Да",G6*Вводные!$B$35,G6)))*Вводные!$B$32+IF(Вводные!$B$38="Да",0,Билеты!$E$32)*(1-Вводные!$B$32) | H17: =IF(H6>=0,H6*Вводные!$B$35,IF(Вводные!$B$37="Да",H6*Вводные!$B$35,H6))-MAX(0,IF(H6>=0,H6*Вводные!$B$35,IF(Вводные!$B$37="Да",H6*Вводные!$B$35,H6)))*Вводные!$B$32+IF(Вводные!$B$38="Да",0,Билеты!$E$32)*(1-Вводные!$B$32)
A18: 0.4 | B18: =IF(B7>=0,B7*Вводные!$B$35,IF(Вводные!$B$37="Да",B7*Вводные!$B$35,B7))-MAX(0,IF(B7>=0,B7*Вводные!$B$35,IF(Вводные!$B$37="Да",B7*Вводные!$B$35,B7)))*Вводные!$B$32+IF(Вводные!$B$38="Да",0,Билеты!$E$32)*(1-Вводные!$B$32) | C18: =IF(C7>=0,C7*Вводные!$B$35,IF(Вводные!$B$37="Да",C7*Вводные!$B$35,C7))-MAX(0,IF(C7>=0,C7*Вводные!$B$35,IF(Вводные!$B$37="Да",C7*Вводные!$B$35,C7)))*Вводные!$B$32+IF(Вводные!$B$38="Да",0,Билеты!$E$32)*(1-Вводные!$B$32) | D18: =IF(D7>=0,D7*Вводные!$B$35,IF(Вводные!$B$37="Да",D7*Вводные!$B$35,D7))-MAX(0,IF(D7>=0,D7*Вводные!$B$35,IF(Вводные!$B$37="Да",D7*Вводные!$B$35,D7)))*Вводные!$B$32+IF(Вводные!$B$38="Да",0,Билеты!$E$32)*(1-Вводные!$B$32) | E18: =IF(E7>=0,E7*Вводные!$B$35,IF(Вводные!$B$37="Да",E7*Вводные!$B$35,E7))-MAX(0,IF(E7>=0,E7*Вводные!$B$35,IF(Вводные!$B$37="Да",E7*Вводные!$B$35,E7)))*Вводные!$B$32+IF(Вводные!$B$38="Да",0,Билеты!$E$32)*(1-Вводные!$B$32) | F18: =IF(F7>=0,F7*Вводные!$B$35,IF(Вводные!$B$37="Да",F7*Вводные!$B$35,F7))-MAX(0,IF(F7>=0,F7*Вводные!$B$35,IF(Вводные!$B$37="Да",F7*Вводные!$B$35,F7)))*Вводные!$B$32+IF(Вводные!$B$38="Да",0,Билеты!$E$32)*(1-Вводные!$B$32) | G18: =IF(G7>=0,G7*Вводные!$B$35,IF(Вводные!$B$37="Да",G7*Вводные!$B$35,G7))-MAX(0,IF(G7>=0,G7*Вводные!$B$35,IF(Вводные!$B$37="Да",G7*Вводные!$B$35,G7)))*Вводные!$B$32+IF(Вводные!$B$38="Да",0,Билеты!$E$32)*(1-Вводные!$B$32) | H18: =IF(H7>=0,H7*Вводные!$B$35,IF(Вводные!$B$37="Да",H7*Вводные!$B$35,H7))-MAX(0,IF(H7>=0,H7*Вводные!$B$35,IF(Вводные!$B$37="Да",H7*Вводные!$B$35,H7)))*Вводные!$B$32+IF(Вводные!$B$38="Да",0,Билеты!$E$32)*(1-Вводные!$B$32)
A19: 0.5 | B19: =IF(B8>=0,B8*Вводные!$B$35,IF(Вводные!$B$37="Да",B8*Вводные!$B$35,B8))-MAX(0,IF(B8>=0,B8*Вводные!$B$35,IF(Вводные!$B$37="Да",B8*Вводные!$B$35,B8)))*Вводные!$B$32+IF(Вводные!$B$38="Да",0,Билеты!$E$32)*(1-Вводные!$B$32) | C19: =IF(C8>=0,C8*Вводные!$B$35,IF(Вводные!$B$37="Да",C8*Вводные!$B$35,C8))-MAX(0,IF(C8>=0,C8*Вводные!$B$35,IF(Вводные!$B$37="Да",C8*Вводные!$B$35,C8)))*Вводные!$B$32+IF(Вводные!$B$38="Да",0,Билеты!$E$32)*(1-Вводные!$B$32) | D19: =IF(D8>=0,D8*Вводные!$B$35,IF(Вводные!$B$37="Да",D8*Вводные!$B$35,D8))-MAX(0,IF(D8>=0,D8*Вводные!$B$35,IF(Вводные!$B$37="Да",D8*Вводные!$B$35,D8)))*Вводные!$B$32+IF(Вводные!$B$38="Да",0,Билеты!$E$32)*(1-Вводные!$B$32) | E19: =IF(E8>=0,E8*Вводные!$B$35,IF(Вводные!$B$37="Да",E8*Вводные!$B$35,E8))-MAX(0,IF(E8>=0,E8*Вводные!$B$35,IF(Вводные!$B$37="Да",E8*Вводные!$B$35,E8)))*Вводные!$B$32+IF(Вводные!$B$38="Да",0,Билеты!$E$32)*(1-Вводные!$B$32) | F19: =IF(F8>=0,F8*Вводные!$B$35,IF(Вводные!$B$37="Да",F8*Вводные!$B$35,F8))-MAX(0,IF(F8>=0,F8*Вводные!$B$35,IF(Вводные!$B$37="Да",F8*Вводные!$B$35,F8)))*Вводные!$B$32+IF(Вводные!$B$38="Да",0,Билеты!$E$32)*(1-Вводные!$B$32) | G19: =IF(G8>=0,G8*Вводные!$B$35,IF(Вводные!$B$37="Да",G8*Вводные!$B$35,G8))-MAX(0,IF(G8>=0,G8*Вводные!$B$35,IF(Вводные!$B$37="Да",G8*Вводные!$B$35,G8)))*Вводные!$B$32+IF(Вводные!$B$38="Да",0,Билеты!$E$32)*(1-Вводные!$B$32) | H19: =IF(H8>=0,H8*Вводные!$B$35,IF(Вводные!$B$37="Да",H8*Вводные!$B$35,H8))-MAX(0,IF(H8>=0,H8*Вводные!$B$35,IF(Вводные!$B$37="Да",H8*Вводные!$B$35,H8)))*Вводные!$B$32+IF(Вводные!$B$38="Да",0,Билеты!$E$32)*(1-Вводные!$B$32)
A20: 0.6 | B20: =IF(B9>=0,B9*Вводные!$B$35,IF(Вводные!$B$37="Да",B9*Вводные!$B$35,B9))-MAX(0,IF(B9>=0,B9*Вводные!$B$35,IF(Вводные!$B$37="Да",B9*Вводные!$B$35,B9)))*Вводные!$B$32+IF(Вводные!$B$38="Да",0,Билеты!$E$32)*(1-Вводные!$B$32) | C20: =IF(C9>=0,C9*Вводные!$B$35,IF(Вводные!$B$37="Да",C9*Вводные!$B$35,C9))-MAX(0,IF(C9>=0,C9*Вводные!$B$35,IF(Вводные!$B$37="Да",C9*Вводные!$B$35,C9)))*Вводные!$B$32+IF(Вводные!$B$38="Да",0,Билеты!$E$32)*(1-Вводные!$B$32) | D20: =IF(D9>=0,D9*Вводные!$B$35,IF(Вводные!$B$37="Да",D9*Вводные!$B$35,D9))-MAX(0,IF(D9>=0,D9*Вводные!$B$35,IF(Вводные!$B$37="Да",D9*Вводные!$B$35,D9)))*Вводные!$B$32+IF(Вводные!$B$38="Да",0,Билеты!$E$32)*(1-Вводные!$B$32) | E20: =IF(E9>=0,E9*Вводные!$B$35,IF(Вводные!$B$37="Да",E9*Вводные!$B$35,E9))-MAX(0,IF(E9>=0,E9*Вводные!$B$35,IF(Вводные!$B$37="Да",E9*Вводные!$B$35,E9)))*Вводные!$B$32+IF(Вводные!$B$38="Да",0,Билеты!$E$32)*(1-Вводные!$B$32) | F20: =IF(F9>=0,F9*Вводные!$B$35,IF(Вводные!$B$37="Да",F9*Вводные!$B$35,F9))-MAX(0,IF(F9>=0,F9*Вводные!$B$35,IF(Вводные!$B$37="Да",F9*Вводные!$B$35,F9)))*Вводные!$B$32+IF(Вводные!$B$38="Да",0,Билеты!$E$32)*(1-Вводные!$B$32) | G20: =IF(G9>=0,G9*Вводные!$B$35,IF(Вводные!$B$37="Да",G9*Вводные!$B$35,G9))-MAX(0,IF(G9>=0,G9*Вводные!$B$35,IF(Вводные!$B$37="Да",G9*Вводные!$B$35,G9)))*Вводные!$B$32+IF(Вводные!$B$38="Да",0,Билеты!$E$32)*(1-Вводные!$B$32) | H20: =IF(H9>=0,H9*Вводные!$B$35,IF(Вводные!$B$37="Да",H9*Вводные!$B$35,H9))-MAX(0,IF(H9>=0,H9*Вводные!$B$35,IF(Вводные!$B$37="Да",H9*Вводные!$B$35,H9)))*Вводные!$B$32+IF(Вводные!$B$38="Да",0,Билеты!$E$32)*(1-Вводные!$B$32)
A21: 0.7 | B21: =IF(B10>=0,B10*Вводные!$B$35,IF(Вводные!$B$37="Да",B10*Вводные!$B$35,B10))-MAX(0,IF(B10>=0,B10*Вводные!$B$35,IF(Вводные!$B$37="Да",B10*Вводные!$B$35,B10)))*Вводные!$B$32+IF(Вводные!$B$38="Да",0,Билеты!$E$32)*(1-Вводные!$B$32) | C21: =IF(C10>=0,C10*Вводные!$B$35,IF(Вводные!$B$37="Да",C10*Вводные!$B$35,C10))-MAX(0,IF(C10>=0,C10*Вводные!$B$35,IF(Вводные!$B$37="Да",C10*Вводные!$B$35,C10)))*Вводные!$B$32+IF(Вводные!$B$38="Да",0,Билеты!$E$32)*(1-Вводные!$B$32) | D21: =IF(D10>=0,D10*Вводные!$B$35,IF(Вводные!$B$37="Да",D10*Вводные!$B$35,D10))-MAX(0,IF(D10>=0,D10*Вводные!$B$35,IF(Вводные!$B$37="Да",D10*Вводные!$B$35,D10)))*Вводные!$B$32+IF(Вводные!$B$38="Да",0,Билеты!$E$32)*(1-Вводные!$B$32) | E21: =IF(E10>=0,E10*Вводные!$B$35,IF(Вводные!$B$37="Да",E10*Вводные!$B$35,E10))-MAX(0,IF(E10>=0,E10*Вводные!$B$35,IF(Вводные!$B$37="Да",E10*Вводные!$B$35,E10)))*Вводные!$B$32+IF(Вводные!$B$38="Да",0,Билеты!$E$32)*(1-Вводные!$B$32) | F21: =IF(F10>=0,F10*Вводные!$B$35,IF(Вводные!$B$37="Да",F10*Вводные!$B$35,F10))-MAX(0,IF(F10>=0,F10*Вводные!$B$35,IF(Вводные!$B$37="Да",F10*Вводные!$B$35,F10)))*Вводные!$B$32+IF(Вводные!$B$38="Да",0,Билеты!$E$32)*(1-Вводные!$B$32) | G21: =IF(G10>=0,G10*Вводные!$B$35,IF(Вводные!$B$37="Да",G10*Вводные!$B$35,G10))-MAX(0,IF(G10>=0,G10*Вводные!$B$35,IF(Вводные!$B$37="Да",G10*Вводные!$B$35,G10)))*Вводные!$B$32+IF(Вводные!$B$38="Да",0,Билеты!$E$32)*(1-Вводные!$B$32) | H21: =IF(H10>=0,H10*Вводные!$B$35,IF(Вводные!$B$37="Да",H10*Вводные!$B$35,H10))-MAX(0,IF(H10>=0,H10*Вводные!$B$35,IF(Вводные!$B$37="Да",H10*Вводные!$B$35,H10)))*Вводные!$B$32+IF(Вводные!$B$38="Да",0,Билеты!$E$32)*(1-Вводные!$B$32)
A22: 0.8 | B22: =IF(B11>=0,B11*Вводные!$B$35,IF(Вводные!$B$37="Да",B11*Вводные!$B$35,B11))-MAX(0,IF(B11>=0,B11*Вводные!$B$35,IF(Вводные!$B$37="Да",B11*Вводные!$B$35,B11)))*Вводные!$B$32+IF(Вводные!$B$38="Да",0,Билеты!$E$32)*(1-Вводные!$B$32) | C22: =IF(C11>=0,C11*Вводные!$B$35,IF(Вводные!$B$37="Да",C11*Вводные!$B$35,C11))-MAX(0,IF(C11>=0,C11*Вводные!$B$35,IF(Вводные!$B$37="Да",C11*Вводные!$B$35,C11)))*Вводные!$B$32+IF(Вводные!$B$38="Да",0,Билеты!$E$32)*(1-Вводные!$B$32) | D22: =IF(D11>=0,D11*Вводные!$B$35,IF(Вводные!$B$37="Да",D11*Вводные!$B$35,D11))-MAX(0,IF(D11>=0,D11*Вводные!$B$35,IF(Вводные!$B$37="Да",D11*Вводные!$B$35,D11)))*Вводные!$B$32+IF(Вводные!$B$38="Да",0,Билеты!$E$32)*(1-Вводные!$B$32) | E22: =IF(E11>=0,E11*Вводные!$B$35,IF(Вводные!$B$37="Да",E11*Вводные!$B$35,E11))-MAX(0,IF(E11>=0,E11*Вводные!$B$35,IF(Вводные!$B$37="Да",E11*Вводные!$B$35,E11)))*Вводные!$B$32+IF(Вводные!$B$38="Да",0,Билеты!$E$32)*(1-Вводные!$B$32) | F22: =IF(F11>=0,F11*Вводные!$B$35,IF(Вводные!$B$37="Да",F11*Вводные!$B$35,F11))-MAX(0,IF(F11>=0,F11*Вводные!$B$35,IF(Вводные!$B$37="Да",F11*Вводные!$B$35,F11)))*Вводные!$B$32+IF(Вводные!$B$38="Да",0,Билеты!$E$32)*(1-Вводные!$B$32) | G22: =IF(G11>=0,G11*Вводные!$B$35,IF(Вводные!$B$37="Да",G11*Вводные!$B$35,G11))-MAX(0,IF(G11>=0,G11*Вводные!$B$35,IF(Вводные!$B$37="Да",G11*Вводные!$B$35,G11)))*Вводные!$B$32+IF(Вводные!$B$38="Да",0,Билеты!$E$32)*(1-Вводные!$B$32) | H22: =IF(H11>=0,H11*Вводные!$B$35,IF(Вводные!$B$37="Да",H11*Вводные!$B$35,H11))-MAX(0,IF(H11>=0,H11*Вводные!$B$35,IF(Вводные!$B$37="Да",H11*Вводные!$B$35,H11)))*Вводные!$B$32+IF(Вводные!$B$38="Да",0,Билеты!$E$32)*(1-Вводные!$B$32)
A23: 0.9 | B23: =IF(B12>=0,B12*Вводные!$B$35,IF(Вводные!$B$37="Да",B12*Вводные!$B$35,B12))-MAX(0,IF(B12>=0,B12*Вводные!$B$35,IF(Вводные!$B$37="Да",B12*Вводные!$B$35,B12)))*Вводные!$B$32+IF(Вводные!$B$38="Да",0,Билеты!$E$32)*(1-Вводные!$B$32) | C23: =IF(C12>=0,C12*Вводные!$B$35,IF(Вводные!$B$37="Да",C12*Вводные!$B$35,C12))-MAX(0,IF(C12>=0,C12*Вводные!$B$35,IF(Вводные!$B$37="Да",C12*Вводные!$B$35,C12)))*Вводные!$B$32+IF(Вводные!$B$38="Да",0,Билеты!$E$32)*(1-Вводные!$B$32) | D23: =IF(D12>=0,D12*Вводные!$B$35,IF(Вводные!$B$37="Да",D12*Вводные!$B$35,D12))-MAX(0,IF(D12>=0,D12*Вводные!$B$35,IF(Вводные!$B$37="Да",D12*Вводные!$B$35,D12)))*Вводные!$B$32+IF(Вводные!$B$38="Да",0,Билеты!$E$32)*(1-Вводные!$B$32) | E23: =IF(E12>=0,E12*Вводные!$B$35,IF(Вводные!$B$37="Да",E12*Вводные!$B$35,E12))-MAX(0,IF(E12>=0,E12*Вводные!$B$35,IF(Вводные!$B$37="Да",E12*Вводные!$B$35,E12)))*Вводные!$B$32+IF(Вводные!$B$38="Да",0,Билеты!$E$32)*(1-Вводные!$B$32) | F23: =IF(F12>=0,F12*Вводные!$B$35,IF(Вводные!$B$37="Да",F12*Вводные!$B$35,F12))-MAX(0,IF(F12>=0,F12*Вводные!$B$35,IF(Вводные!$B$37="Да",F12*Вводные!$B$35,F12)))*Вводные!$B$32+IF(Вводные!$B$38="Да",0,Билеты!$E$32)*(1-Вводные!$B$32) | G23: =IF(G12>=0,G12*Вводные!$B$35,IF(Вводные!$B$37="Да",G12*Вводные!$B$35,G12))-MAX(0,IF(G12>=0,G12*Вводные!$B$35,IF(Вводные!$B$37="Да",G12*Вводные!$B$35,G12)))*Вводные!$B$32+IF(Вводные!$B$38="Да",0,Билеты!$E$32)*(1-Вводные!$B$32) | H23: =IF(H12>=0,H12*Вводные!$B$35,IF(Вводные!$B$37="Да",H12*Вводные!$B$35,H12))-MAX(0,IF(H12>=0,H12*Вводные!$B$35,IF(Вводные!$B$37="Да",H12*Вводные!$B$35,H12)))*Вводные!$B$32+IF(Вводные!$B$38="Да",0,Билеты!$E$32)*(1-Вводные!$B$32)
A24: 1 | B24: =IF(B13>=0,B13*Вводные!$B$35,IF(Вводные!$B$37="Да",B13*Вводные!$B$35,B13))-MAX(0,IF(B13>=0,B13*Вводные!$B$35,IF(Вводные!$B$37="Да",B13*Вводные!$B$35,B13)))*Вводные!$B$32+IF(Вводные!$B$38="Да",0,Билеты!$E$32)*(1-Вводные!$B$32) | C24: =IF(C13>=0,C13*Вводные!$B$35,IF(Вводные!$B$37="Да",C13*Вводные!$B$35,C13))-MAX(0,IF(C13>=0,C13*Вводные!$B$35,IF(Вводные!$B$37="Да",C13*Вводные!$B$35,C13)))*Вводные!$B$32+IF(Вводные!$B$38="Да",0,Билеты!$E$32)*(1-Вводные!$B$32) | D24: =IF(D13>=0,D13*Вводные!$B$35,IF(Вводные!$B$37="Да",D13*Вводные!$B$35,D13))-MAX(0,IF(D13>=0,D13*Вводные!$B$35,IF(Вводные!$B$37="Да",D13*Вводные!$B$35,D13)))*Вводные!$B$32+IF(Вводные!$B$38="Да",0,Билеты!$E$32)*(1-Вводные!$B$32) | E24: =IF(E13>=0,E13*Вводные!$B$35,IF(Вводные!$B$37="Да",E13*Вводные!$B$35,E13))-MAX(0,IF(E13>=0,E13*Вводные!$B$35,IF(Вводные!$B$37="Да",E13*Вводные!$B$35,E13)))*Вводные!$B$32+IF(Вводные!$B$38="Да",0,Билеты!$E$32)*(1-Вводные!$B$32) | F24: =IF(F13>=0,F13*Вводные!$B$35,IF(Вводные!$B$37="Да",F13*Вводные!$B$35,F13))-MAX(0,IF(F13>=0,F13*Вводные!$B$35,IF(Вводные!$B$37="Да",F13*Вводные!$B$35,F13)))*Вводные!$B$32+IF(Вводные!$B$38="Да",0,Билеты!$E$32)*(1-Вводные!$B$32) | G24: =IF(G13>=0,G13*Вводные!$B$35,IF(Вводные!$B$37="Да",G13*Вводные!$B$35,G13))-MAX(0,IF(G13>=0,G13*Вводные!$B$35,IF(Вводные!$B$37="Да",G13*Вводные!$B$35,G13)))*Вводные!$B$32+IF(Вводные!$B$38="Да",0,Билеты!$E$32)*(1-Вводные!$B$32) | H24: =IF(H13>=0,H13*Вводные!$B$35,IF(Вводные!$B$37="Да",H13*Вводные!$B$35,H13))-MAX(0,IF(H13>=0,H13*Вводные!$B$35,IF(Вводные!$B$37="Да",H13*Вводные!$B$35,H13)))*Вводные!$B$32+IF(Вводные!$B$38="Да",0,Билеты!$E$32)*(1-Вводные!$B$32)
A27: Точка безубыточности при разной средней цене билета
A28: Средняя цена, ₽ | B28: 1500 | C28: 2000 | D28: 2500 | E28: 3000 | F28: 3500 | G28: 4000 | H28: 4500
