Workbook

Sheet Дашборд
A1: КОНЦЕРТ: ИТОГОВАЯ ЭКОНОМИКА
A2: Один экран с главными цифрами. Всё пересчитывается автоматически — меняйте вводные на листах «Вводные», «Билеты», «Технические», «Гонорары», «Маркетинг», «Прочие».
B4: Проект | C4: =Вводные!$B$5 -> — укажите название — | E4: Дата / площадка | F4: =Вводные!$B$7&" · "&Вводные!$B$8 -> — ДД.ММ.ГГГГ, 20:00 — · — клуб —
A6: ЭТАП 1 — ДО РАЗДЕЛА ПРИБЫЛИ
B7: Валовой сбор | C7: =Экономика!$C$6 -> 466100 | E7: Продано билетов, шт | F7: =Билеты!$E$12 -> 202
B8: Налоги УСН 6% | C8: =Экономика!$C$7 -> -27966 | E8: Отчисления в РАО 8% | F8: =Экономика!$C$8 -> -37288
B9: Технические расходы | C9: =Экономика!$C$9 -> -154500 | E9: Средняя цена платного билета | F9: =Билеты!$B$19 -> 2427.6042
B10: ПРИБЫЛЬ (делится пополам) | C10: =Экономика!$C$30 -> 246346 | E10: ПРИБЫЛЬ ОРГАНИЗАТОРА (50%) | F10: =Экономика!$C$34 -> 123173
A12: ЭТАП 2 — РАСХОДЫ ИЗ ПРИБЫЛИ ОРГАНИЗАТОРА
B13: Налоги 7% | C13: =Экономика!$C$37 -> -8622.11 | E13: Банковские комиссии 1% | F13: =Экономика!$C$38 -> -1231.73
B14: Гонорары артистам | C14: =Экономика!$C$39 -> -49000 | E14: Маркетинг и PR | F14: =Экономика!$C$48 -> -60000
B15: Прочие расходы | C15: =Экономика!$C$57 -> -76450 | E15: Итого расходов этапа 2 | F15: =Экономика!$C$37+Экономика!$C$38+Экономика!$C$39+Экономика!$C$48+Экономика!$C$57 -> -195303.84
B16: ЧИСТЫЙ ДОХОД ОРГАНИЗАТОРА | C16: =Экономика!$C$72 -> -72130.84 | E16: Рентабельность к сбору | F16: =Экономика!$C$81 -> -0.154754
A18: УСТОЙЧИВОСТЬ ПРОЕКТА
B19: Валовой сбор для выхода в ноль | C19: =Экономика!$C$77 -> 648432.76 | E19: Точка безубыточности, платных билетов | F19: =Экономика!$C$78 -> 268
B20: Точка безубыточности, % зала | C20: =Экономика!$C$79 -> 0.93986111 | E20: Запас прочности | F20: =Экономика!$C$80 -> -0.39583333
B22: ВЕРДИКТ | C22: =Экономика!$C$83 -> УБЫТОК. Нужен сбор от 648 433 ₽ (94% зала), чтобы выйти в ноль
A24: СЦЕНАРИИ — ЧИСТЫЙ ДОХОД ОРГАНИЗАТОРА
B25: Пессимистичный | C25: Базовый | D25: Оптимистичный | E25: Аншлаг
B26: =Сценарии!B24 -> -147038.94 | C26: =Сценарии!C24 -> -72130.84 | D26: =Сценарии!D24 -> -9707.4265 | E26: =Сценарии!E24 -> 17182.659
B27: =Сценарии!B5 -> 0.4 | C27: =Сценарии!C5 -> 0.67333333 | D27: =Сценарии!D5 -> 0.9 | E27: =Сценарии!E5 -> 1 | F27: ← заполняемость зала
A29: ЧТО УТОЧНИТЬ ПЕРЕД ЗАПУСКОМ
B30: 1. Технический райдер и смету по звуку — пришлите файлом, перенесу построчно на лист «Технические».
B31: 2. Ставка РАО: у вас стоит 8%. Базовый тариф для концертов обычно 5% — сверьте с договором, разница в 3 п.п. от сбора это заметные деньги.
B32: 3. Кто получает деньги от билетов физически — вы или площадка. От этого зависит, у кого возникает доход и кто платит УСН 6% на этапе 1.
B33: 4. Комиссия билетного оператора: если она удерживается из кассы, её место на этапе 1, а не в прочих расходах. Сейчас стоит 0.
B34: 5. Что именно входит в «техническое обеспечение площадки» по договору и кто это оплачивает.
B35: 6. Делится ли убыток пополам, или он только ваш. Сейчас в модели — только ваш.
B36: 7. Можно ли вычитать гонорары и маркетинг ДО раздела прибыли. Это главный рычаг — переключатели на листе «Вводные».

Sheet Вводные
A1: ВВОДНЫЕ ДАННЫЕ И СТАВКИ
A2: Синие ячейки на жёлтом фоне — вводные, их можно менять. Чёрные — формулы. Зелёные — ссылки на другие листы.
A4: 1. ПАРАМЕТРЫ СОБЫТИЯ
A5: Название концерта | B5: — укажите название —
A6: Артист / состав | B6: — укажите —
A7: Дата и время | B7: — ДД.ММ.ГГГГ, 20:00 —
A8: Площадка | B8: — клуб —
A9: Город | B9: — город —
A11: 2. ЗАЛ И ПОСЕЩАЕМОСТЬ
A12: Вместимость зала, чел. | B12: 300
A13: Заполняемость — пессимистичный сценарий | B13: 0.4 | C13: Базовый сценарий берётся с листа «Билеты» — там задана продажа по категориям
A14: Заполняемость — оптимистичный сценарий | B14: 0.9
A15: Заполняемость — аншлаг | B15: 1
A17: 3. СТАВКИ ЭТАПА 1 — С ВАЛОВОГО СБОРА
A18: Налоги УСН, % | B18: 0.06 | C18: Начисляется на весь валовой сбор
A19: Отчисления в РАО, % | B19: 0.08 | C19: Начисляется на весь валовой сбор
A21: 4. ТЕХНИЧЕСКИЕ РАСХОДЫ (АРЕНДА ЗВУКА И ОБЕСПЕЧЕНИЕ ПЛОЩАДКИ)
A22: Как считать: «Из сметы» или «Фиксированной суммой» | B22: Из сметы | C22: Пока нет точных цифр — поставьте «Фиксированной суммой» и впишите её ниже
A23: Фиксированная сумма технических расходов, ₽ | B23: 150000 | C23: Используется, только если выбран режим «Фиксированной суммой»
A25: 5. РАЗДЕЛ ПРИБЫЛИ С ПЛОЩАДКОЙ
A26: Доля организатора в прибыли, % | B26: 0.5
A27: Доля площадки в прибыли, % | B27: =1-Вводные!$B$26 -> 0.5
A28: Убыток делится с площадкой? (Да/Нет) | B28: Нет | C28: Если «Нет» — весь убыток ваш, а прибыль только наполовину
A30: 6. СТАВКИ ЭТАПА 2 — С ПРИБЫЛИ ОРГАНИЗАТОРА
A31: Налоги, % | B31: 0.07 | C31: С половины прибыли, полученной от площадки
A32: Банковские комиссии, % | B32: 0.01
A33: ИТОГО ставка этапа 2, % | B33: =Вводные!$B$31+Вводные!$B$32 -> 0.08
A35: 7. ЧТО ВЫЧИТАТЬ ДО РАЗДЕЛА ПРИБЫЛИ (переговорный рычаг)
A36: По вашей схеме всё это вычитается ПОСЛЕ раздела, из вашей половины. Переключите на «Да», чтобы увидеть, как изменится экономика, если договориться вычитать эти расходы до раздела.
A37: Гонорары артистам вычитать до раздела? | B37: Нет
A38: Маркетинг и PR вычитать до раздела? | B38: Нет
A39: Прочие расходы вычитать до раздела? | B39: Нет
A41: 8. ПРОЧЕЕ
A42: Резерв на непредвиденное, % от прочих расходов | B42: 0.1

Sheet Билеты
A1: БИЛЕТНАЯ МАТРИЦА
A2: Базовый сценарий строится здесь: цена, квота мест и ожидаемый процент продажи по каждой категории.
A4: СТРУКТУРА БИЛЕТОВ
A5: Категория билета | B5: Цена, ₽ | C5: Квота, мест | D5: Ожид. продажа, % | E5: Продано, шт | F5: Валовой сбор, ₽ | G5: Доля в сборе | H5: Комментарий
A6: Ранняя пташка (early bird) | B6: 1800 | C6: 60 | D6: 0.95 | E6: =ROUND(C6*D6,0) -> 57 | F6: =B6*E6 -> 102600 | G6: =IFERROR(F6/$F$12,0) -> 0.22012444 | H6: Первые 2 недели, ограниченная квота. Ранние деньги на маркетинг
A7: Стандарт (предпродажа) | B7: 2500 | C7: 150 | D7: 0.6 | E7: =ROUND(C7*D7,0) -> 90 | F7: =B7*E7 -> 225000 | G7: =IFERROR(F7/$F$12,0) -> 0.48272903 | H7: Основная квота зала
A8: Стандарт (на входе, в день концерта) | B8: 2800 | C8: 40 | D8: 0.5 | E8: =ROUND(C8*D8,0) -> 20 | F8: =B8*E8 -> 56000 | G8: =IFERROR(F8/$F$12,0) -> 0.12014589 | H8: Цена на входе выше — стимул покупать заранее
A9: Фан-зона у сцены / VIP | B9: 4000 | C9: 30 | D9: 0.6 | E9: =ROUND(C9*D9,0) -> 18 | F9: =B9*E9 -> 72000 | G9: =IFERROR(F9/$F$12,0) -> 0.15447329 | H9: Первые ряды, отдельный вход
A10: Льготный (студенты) | B10: 1500 | C10: 10 | D10: 0.7 | E10: =ROUND(C10*D10,0) -> 7 | F10: =B10*E10 -> 10500 | G10: =IFERROR(F10/$F$12,0) -> 0.022527355 | H10: Заполняет зал в будни
A11: Промо, пресс, гости артиста | B11: 0 | C11: 10 | D11: 1 | E11: =ROUND(C11*D11,0) -> 10 | F11: =B11*E11 -> 0 | G11: =IFERROR(F11/$F$12,0) -> 0 | H11: Денег не приносят, но занимают места
A12: ИТОГО | C12: =SUM(C6:C11) -> 300 | E12: =SUM(E6:E11) -> 202 | F12: =SUM(F6:F11) -> 466100 | G12: =SUM(G6:G11) -> 1
A14: КОНТРОЛЬНЫЕ ПОКАЗАТЕЛИ
A15: Проверка: сумма квот = вместимость зала? | B15: =IF(Билеты!$C$12=Вводные!$B$12,"OK — квоты сходятся с залом","ВНИМАНИЕ: квоты ("&Билеты!$C$12&") ≠ вместимость ("&Вводные!$B$12&")") -> OK — квоты сходятся с залом
A16: Продано билетов всего, шт | B16: =Билеты!$E$12 -> 202
A17: в том числе платных, шт | B17: =SUMIF(B6:B11,">0",E6:E11) -> 192
A18: Валовой сбор (box office), ₽ | B18: =Билеты!$F$12 -> 466100
A19: Средняя цена платного билета, ₽ | B19: =IFERROR(Билеты!$F$12/Билеты!$B$17,0) -> 2427.6042
A20: Доход на одно место зала (yield), ₽ | B20: =IFERROR(Билеты!$F$12/Вводные!$B$12,0) -> 1553.6667
A21: Фактическая заполняемость зала, % | B21: =IFERROR(Билеты!$E$12/Вводные!$B$12,0) -> 0.67333333
A22: Доля платных билетов от всех проходов, % | B22: =IFERROR(Билеты!$B$17/Билеты!$E$12,0) -> 0.95049505

Sheet Технические
A1: ТЕХНИЧЕСКИЕ РАСХОДЫ: АРЕНДА ЗВУКА И ОБЕСПЕЧЕНИЕ ПЛОЩАДКИ
A2: Этап 1 — вычитается из валового сбора ДО раздела прибыли с площадкой. Пришлёте технический райдер — заменю строки на реальные позиции и цены.
A4: Статья расхода | B4: Кол-во | C4: Ед. | D4: Цена за ед., ₽ | E4: Сумма, ₽ | F4: Комментарий
A5: Аренда зала (смена) | B5: 1 | C5: смена | D5: 20000 | E5: =B5*D5 -> 20000 | F5: При сделке 50/50 часто не выставляется — уточните в договоре
A6: Аренда звукового комплекта PA | B6: 1 | C6: компл. | D6: 25000 | E6: =B6*D6 -> 25000 | F6: Основная позиция технической сметы
A7: Микрофоны, радиосистемы, стойки | B7: 1 | C7: компл. | D7: 8000 | E7: =B7*D7 -> 8000 | F7: Под конкретный состав почти всегда докупается
A8: Мониторная линия / in-ear | B8: 1 | C8: компл. | D8: 10000 | E8: =B8*D8 -> 10000 | F8: Критично для качества исполнения на сцене
A9: Звукорежиссёр FOH | B9: 1 | C9: смена | D9: 15000 | E9: =B9*D9 -> 15000 | F9: Свой инженер — предсказуемый звук
A10: Мониторный инженер | B10: 0 | C10: смена | D10: 12000 | E10: =B10*D10 -> 0 | F10: В клубе часто совмещается с FOH
A11: Световое оборудование | B11: 1 | C11: компл. | D11: 15000 | E11: =B11*D11 -> 15000
A12: Художник по свету / оператор | B12: 1 | C12: смена | D12: 8000 | E12: =B12*D12 -> 8000 | F12: Свет под программу, а не «дискотека по кнопке»
A13: Бэклайн: барабаны, усилители, клавиши | B13: 0 | C13: компл. | D13: 20000 | E13: =B13*D13 -> 0 | F13: Поставьте 1, если бэклайн привозной
A14: Экран, проекция, видеоконтент | B14: 0 | C14: компл. | D14: 18000 | E14: =B14*D14 -> 0 | F14: Поставьте 1, если в программе есть видеоряд
A15: Электрика, кабели, распределение | B15: 1 | C15: компл. | D15: 3000 | E15: =B15*D15 -> 3000
A16: Монтаж, демонтаж, погрузка | B16: 3 | C16: чел. | D16: 3500 | E16: =B16*D16 -> 10500 | F16: Разгрузка и погрузка оборудования
A17: Охрана | B17: 3 | C17: чел. | D17: 4000 | E17: =B17*D17 -> 12000 | F17: Ориентир — 1 человек на 75–100 гостей
A18: Билетный контроль и гардероб | B18: 3 | C18: чел. | D18: 3000 | E18: =B18*D18 -> 9000
A19: Уборка до и после | B19: 2 | C19: чел. | D19: 3000 | E19: =B19*D19 -> 6000
A20: Дежурный медик | B20: 1 | C20: смена | D20: 5000 | E20: =B20*D20 -> 5000 | F20: Требование для массовых мероприятий
A21: Администратор площадки | B21: 1 | C21: смена | D21: 8000 | E21: =B21*D21 -> 8000
A22: ИТОГО | E22: =SUM(E5:E21) -> 154500

Sheet Гонорары
A1: ГОНОРАРЫ АРТИСТАМ
A2: Этап 2 — по вашей схеме вычитается из половины прибыли, уже полученной организатором. Переключатель «вычитать до раздела» — на листе «Вводные».
A4: Статья расхода | B4: Кол-во | C4: Ед. | D4: Цена за ед., ₽ | E4: Сумма, ₽ | F4: Комментарий
A5: Артист / хедлайнер | B5: 1 | C5: выступл. | D5: 25000 | E5: =B5*D5 -> 25000 | F5: Основной гонорар по договору
A6: Музыкант: гитара | B6: 1 | C6: выступл. | D6: 8000 | E6: =B6*D6 -> 8000
A7: Музыкант: бас | B7: 1 | C7: выступл. | D7: 8000 | E7: =B7*D7 -> 8000
A8: Музыкант: барабаны | B8: 1 | C8: выступл. | D8: 8000 | E8: =B8*D8 -> 8000
A9: Музыкант: клавиши | B9: 0 | C9: выступл. | D9: 8000 | E9: =B9*D9 -> 0 | F9: Поставьте 1, если есть в составе
A10: Разогрев / support act | B10: 0 | C10: выступл. | D10: 10000 | E10: =B10*D10 -> 0 | F10: Часто выступает за билеты и промо
A11: Ведущий / конферансье | B11: 0 | C11: выступл. | D11: 8000 | E11: =B11*D11 -> 0
A12: Налоги и взносы с гонораров | B12: 0 | C12: компл. | D12: 15000 | E12: =B12*D12 -> 0 | F12: Если музыканты не самозанятые — нагрузка ложится на вас
A13: ИТОГО | E13: =SUM(E5:E12) -> 49000

Sheet Прочие
A1: ПРОЧИЕ РАСХОДЫ
A2: Этап 2 — вычитается из половины прибыли организатора. Резерв считается процентом от суммы строк выше.
A4: Статья расхода | B4: Кол-во | C4: Ед. | D4: Цена за ед., ₽ | E4: Сумма, ₽ | F4: Комментарий
A5: Комиссия билетного оператора | B5: 0 | C5: компл. | D5: 40000 | E5: =B5*D5 -> 0 | F5: ВАЖНО: если оператор удерживает её из кассы, она относится к этапу 1 — скажите, и перенесу
A6: Полиграфия: афиши, флаеры | B6: 1 | C6: тираж | D6: 12000 | E6: =B6*D6 -> 12000 | F6: Печать. Размещение — в бюджете маркетинга
A7: Бейджи, браслеты, программки | B7: 1 | C7: тираж | D7: 5000 | E7: =B7*D7 -> 5000
A8: Оформление сцены и зала, декор | B8: 0 | C8: компл. | D8: 15000 | E8: =B8*D8 -> 0 | F8: Сильно влияет на восприятие и качество контента
A9: Репетиции, аренда репбазы | B9: 2 | C9: смена | D9: 6000 | E9: =B9*D9 -> 12000
A10: Транспорт оборудования | B10: 2 | C10: рейс | D10: 6000 | E10: =B10*D10 -> 12000 | F10: Туда и обратно
A11: Трансфер и проживание команды | B11: 0 | C11: компл. | D11: 25000 | E11: =B11*D11 -> 0 | F11: Заполните, если команда не из этого города
A12: Кейтеринг и райдер бэкстейджа | B12: 15 | C12: чел. | D12: 700 | E12: =B12*D12 -> 10500 | F12: По числу людей на площадке, включая техников
A13: Фотограф | B13: 1 | C13: смена | D13: 12000 | E13: =B13*D13 -> 12000 | F13: Контент окупается в промо следующего концерта
A14: Видеосъёмка концерта | B14: 0 | C14: смена | D14: 25000 | E14: =B14*D14 -> 0 | F14: Материал для клипов и питчей площадкам
A15: Юридическое сопровождение | B15: 1 | C15: проект | D15: 6000 | E15: =B15*D15 -> 6000 | F15: Договоры с площадкой, артистами, лицензия РАО
A16: Онлайн-касса, ОФД | B16: 0 | C16: проект | D16: 3000 | E16: =B16*D16 -> 0 | F16: Если часть билетов продаёте сами
A17: Страхование мероприятия | B17: 0 | C17: полис | D17: 12000 | E17: =B17*D17 -> 0 | F17: Рекомендую при бюджете свыше 500 000 ₽
A18: Резерв на непредвиденное | E18: =SUM(E5:E17)*Вводные!$B$42 -> 6950 | F18: Ставка резерва задаётся на листе «Вводные»
A19: ИТОГО | E19: =SUM(E5:E18) -> 76450

Sheet Маркетинг
A1: МАРКЕТИНГ И PR: БЮДЖЕТ, ВОРОНКА, СТОИМОСТЬ БИЛЕТА
A2: Этап 2 — вычитается из половины прибыли организатора. Каждый канал считается до билета: охват → отклик → покупка.
A4: КАНАЛЫ ПРОДВИЖЕНИЯ
A5: Канал | B5: Бюджет, ₽ | C5: Прогноз охвата, чел. | D5: Отклик (CTR), % | E5: Конверсия в покупку, % | F5: Прогноз билетов, шт | G5: CPA, ₽ за билет | H5: Комментарий
A6: Таргетированная реклама VK | B6: 20000 | C6: 120000 | D6: 0.012 | E6: 0.03 | F6: =ROUND(C6*D6*E6,0) -> 43 | G6: =IFERROR(B6/F6,0) -> 465.11628 | H6: Основной платный канал. Гео + интересы + look-alike
A7: Посевы в Telegram-каналах | B7: 15000 | C7: 55000 | D7: 0.02 | E7: 0.04 | F7: =ROUND(C7*D7*E7,0) -> 44 | G7: =IFERROR(B7/F7,0) -> 340.90909 | H7: Городские и жанровые каналы. Просите статистику до оплаты
A8: Блогеры и лидеры мнений | B8: 10000 | C8: 35000 | D8: 0.025 | E8: 0.035 | F8: =ROUND(C8*D8*E8,0) -> 31 | G8: =IFERROR(B8/F8,0) -> 322.58065 | H8: Часть работает по бартеру за билеты
A9: Наружная реклама и расклейка афиш | B9: 5000 | C9: 20000 | D9: 0.005 | E9: 0.05 | F9: =ROUND(C9*D9*E9,0) -> 5 | G9: =IFERROR(B9/F9,0) -> 1000 | H9: Плохо атрибутируется — нужен отдельный промокод
A10: Городские афиши: Яндекс.Афиша, KudaGo | B10: 0 | C10: 25000 | D10: 0.01 | E10: 0.04 | F10: =ROUND(C10*D10*E10,0) -> 10 | G10: =IFERROR(B10/F10,0) -> 0 | H10: Бесплатно. Подавать за 3–4 недели
A11: PR: пресс-релиз, СМИ, интервью | B11: 3000 | C11: 15000 | D11: 0.01 | E11: 0.03 | F11: =ROUND(C11*D11*E11,0) -> 5 | G11: =IFERROR(B11/F11,0) -> 600 | H11: Даёт доверие и перепечатки, а не прямые продажи
A12: Email и база подписчиков | B12: 1000 | C12: 6000 | D12: 0.12 | E12: 0.08 | F12: =ROUND(C12*D12*E12,0) -> 58 | G12: =IFERROR(B12/F12,0) -> 17.241379 | H12: Самый дешёвый билет. Базу надо собирать заранее
A13: Продакшн контента: дизайн, тизер, фото | B13: 6000 | C13: 0 | D13: 0 | E13: 0 | F13: =ROUND(C13*D13*E13,0) -> 0 | G13: =IFERROR(B13/F13,0) -> 0 | H13: Не продаёт напрямую, но без него не работают каналы выше
A14: ИТОГО МАРКЕТИНГ И PR | B14: =SUM(B6:B13) -> 60000 | C14: =SUM(C6:C13) -> 276000 | F14: =SUM(F6:F13) -> 196 | G14: =IFERROR(B14/F14,0) -> 306.12245
A16: ПРОВЕРКА ЗДОРОВЬЯ МАРКЕТИНГА
A17: Бюджет маркетинга и PR, ₽ | B17: =Маркетинг!$B$14 -> 60000
A18: Прогноз билетов от маркетинга, шт | B18: =Маркетинг!$F$14 -> 196
A19: План продаж по билетной матрице, шт | B19: =Билеты!$B$17 -> 192
A20: Покрытие плана продаж маркетингом, % | B20: =IFERROR(Маркетинг!$F$14/Билеты!$B$17,0) -> 1.0208333 | C20: Ниже 100% — план продаж ничем не обеспечен
A21: CPA к средней цене билета, % | B21: =IFERROR(Маркетинг!$G$14/Билеты!$B$19,0) -> 0.12610064 | C21: Здоровый диапазон — до 25%
A22: Доля маркетинга в валовом сборе, % | B22: =IFERROR(Маркетинг!$B$14/Билеты!$F$12,0) -> 0.12872774 | C22: Ориентир для клубного концерта — 10–15%
A23: Вердикт | B23: =IF(Маркетинг!$B$22>0.2,"ПЕРЕРАСХОД: маркетинг забирает больше 20% сбора",IF(Маркетинг!$B$20<1,"РИСК: маркетинг не покрывает план продаж","Норма: бюджет и план продаж сбалансированы")) -> Норма: бюджет и план продаж сбалансированы

Sheet Экономика
A1: ЭКОНОМИКА КОНЦЕРТА
A2: Этап 1: валовой сбор − УСН − РАО − технические расходы = прибыль. Прибыль делится пополам. Этап 2: из половины организатора вычитаются налоги 7%, банк 1%, гонорары, маркетинг и прочие расходы.
A4: Показатель | B4: Расшифровка, ₽ | C4: Сумма, ₽ | D4: % от сбора | E4: Комментарий
A5: ЭТАП 1 — ДО РАЗДЕЛА ПРИБЫЛИ С ПЛОЩАДКОЙ
A6: 1. ВАЛОВОЙ СБОР | C6: =Билеты!$F$12 -> 466100 | D6: =IFERROR(C6/$C$6,0) -> 1 | E6: Вся выручка от продажи билетов — лист «Билеты»
A7: 2. Налоги УСН 6% | C7: =-Экономика!$C$6*Вводные!$B$18 -> -27966 | D7: =IFERROR(C7/$C$6,0) -> -0.06 | E7: Ставка — на листе «Вводные»
A8: 3. Отчисления в РАО 8% | C8: =-Экономика!$C$6*Вводные!$B$19 -> -37288 | D8: =IFERROR(C8/$C$6,0) -> -0.08 | E8: Ставка 8% по вашим условиям. Базовый тариф РАО для концертов обычно 5% — стоит сверить с договором
A9: 4. Технические расходы: аренда звука и обеспечение площадки | C9: =-IF(Вводные!$B$22="Фиксированной суммой",Вводные!$B$23,Технические!$E$22) -> -154500 | D9: =IFERROR(C9/$C$6,0) -> -0.33147393 | E9: Режим «из сметы» или «фиксированной суммой» — на листе «Вводные»
A10: =Технические!$A$5 -> Аренда зала (смена) | B10: =-Технические!$E$5 -> -20000
A11: =Технические!$A$6 -> Аренда звукового комплекта PA | B11: =-Технические!$E$6 -> -25000
A12: =Технические!$A$7 -> Микрофоны, радиосистемы, стойки | B12: =-Технические!$E$7 -> -8000
A13: =Технические!$A$8 -> Мониторная линия / in-ear | B13: =-Технические!$E$8 -> -10000
A14: =Технические!$A$9 -> Звукорежиссёр FOH | B14: =-Технические!$E$9 -> -15000
A15: =Технические!$A$10 -> Мониторный инженер | B15: =-Технические!$E$10 -> 0
A16: =Технические!$A$11 -> Световое оборудование | B16: =-Технические!$E$11 -> -15000
A17: =Технические!$A$12 -> Художник по свету / оператор | B17: =-Технические!$E$12 -> -8000
A18: =Технические!$A$13 -> Бэклайн: барабаны, усилители, клавиши | B18: =-Технические!$E$13 -> 0
A19: =Технические!$A$14 -> Экран, проекция, видеоконтент | B19: =-Технические!$E$14 -> 0
A20: =Технические!$A$15 -> Электрика, кабели, распределение | B20: =-Технические!$E$15 -> -3000
A21: =Технические!$A$16 -> Монтаж, демонтаж, погрузка | B21: =-Технические!$E$16 -> -10500
A22: =Технические!$A$17 -> Охрана | B22: =-Технические!$E$17 -> -12000
A23: =Технические!$A$18 -> Билетный контроль и гардероб | B23: =-Технические!$E$18 -> -9000
A24: =Технические!$A$19 -> Уборка до и после | B24: =-Технические!$E$19 -> -6000
A25: =Технические!$A$20 -> Дежурный медик | B25: =-Технические!$E$20 -> -5000
A26: =Технические!$A$21 -> Администратор площадки | B26: =-Технические!$E$21 -> -8000
A27: Гонорары артистам — если вычитаются до раздела | C27: =-IF(Вводные!$B$37="Да",Гонорары!$E$13,0) -> 0 | D27: =IFERROR(C27/$C$6,0) -> 0 | E27: По вашей схеме = 0. Переключатель на листе «Вводные»
A28: Маркетинг и PR — если вычитается до раздела | C28: =-IF(Вводные!$B$38="Да",Маркетинг!$B$14,0) -> 0 | D28: =IFERROR(C28/$C$6,0) -> 0
A29: Прочие расходы — если вычитаются до раздела | C29: =-IF(Вводные!$B$39="Да",Прочие!$E$19,0) -> 0 | D29: =IFERROR(C29/$C$6,0) -> 0
A30: 5. ПРИБЫЛЬ | C30: =Экономика!$C$6+Экономика!$C$7+Экономика!$C$8+Экономика!$C$9+Экономика!$C$27+Экономика!$C$28+Экономика!$C$29 -> 246346 | D30: =IFERROR(C30/$C$6,0) -> 0.52852607
A32: РАЗДЕЛ ПРИБЫЛИ ПОПОЛАМ
A33: Доля площадки | C33: =-IF(Экономика!$C$30>=0,Экономика!$C$30*Вводные!$B$27,IF(Вводные!$B$28="Да",Экономика!$C$30*Вводные!$B$27,0)) -> -123173 | D33: =IFERROR(C33/$C$6,0) -> -0.26426303 | E33: При убытке площадка не участвует, если в договоре не сказано иное
A34: ПРИБЫЛЬ ОРГАНИЗАТОРА | C34: =Экономика!$C$30+Экономика!$C$33 -> 123173 | D34: =IFERROR(C34/$C$6,0) -> 0.26426303 | E34: Это база, из которой дальше вычитается всё на этапе 2
A36: ЭТАП 2 — РАСХОДЫ ИЗ ПРИБЫЛИ ОРГАНИЗАТОРА
A37: Налоги 7% | C37: =-MAX(0,Экономика!$C$34)*Вводные!$B$31 -> -8622.11 | D37: =IFERROR(C37/$C$6,0) -> -0.018498412 | E37: С прибыли организатора, полученной от площадки
A38: Банковские комиссии 1% | C38: =-MAX(0,Экономика!$C$34)*Вводные!$B$32 -> -1231.73 | D38: =IFERROR(C38/$C$6,0) -> -0.0026426303
A39: Гонорары артистам | C39: =-IF(Вводные!$B$37="Нет",Гонорары!$E$13,0) -> -49000 | D39: =IFERROR(C39/$C$6,0) -> -0.10512766
A40: =Гонорары!$A$5 -> Артист / хедлайнер | B40: =-Гонорары!$E$5 -> -25000
A41: =Гонорары!$A$6 -> Музыкант: гитара | B41: =-Гонорары!$E$6 -> -8000
A42: =Гонорары!$A$7 -> Музыкант: бас | B42: =-Гонорары!$E$7 -> -8000
A43: =Гонорары!$A$8 -> Музыкант: барабаны | B43: =-Гонорары!$E$8 -> -8000
...

Sheet Сценарии
A1: СЦЕНАРИИ: ОТ ПРОВАЛА ДО АНШЛАГА
A2: Цены и вся смета во всех сценариях одинаковые — меняется только заполняемость зала. Последний столбец показывает, где проходит граница нуля.
A4: Показатель | B4: Пессимистичный | C4: БАЗОВЫЙ | D4: Оптимистичный | E4: Аншлаг | F4: Точка безубыточности | G4: Комментарий
A5: Заполняемость зала, % | B5: =Вводные!$B$13 -> 0.4 | C5: =Билеты!$B$21 -> 0.67333333 | D5: =Вводные!$B$14 -> 0.9 | E5: =Вводные!$B$15 -> 1 | F5: =Экономика!$C$79 -> 0.93986111 | G5: Пессимистичный и оптимистичный задаются на листе «Вводные»
A6: Продано билетов всего, шт | B6: =ROUND(Вводные!$B$12*B5,0) -> 120 | C6: =Билеты!$E$12 -> 202 | D6: =ROUND(Вводные!$B$12*D5,0) -> 270 | E6: =ROUND(Вводные!$B$12*E5,0) -> 300 | F6: =ROUND(Вводные!$B$12*F5,0) -> 282
A7: в том числе платных, шт | B7: =ROUND(B6*Билеты!$B$22,0) -> 114 | C7: =Билеты!$B$17 -> 192 | D7: =ROUND(D6*Билеты!$B$22,0) -> 257 | E7: =ROUND(E6*Билеты!$B$22,0) -> 285 | F7: =ROUND(F6*Билеты!$B$22,0) -> 268
A8: Средняя цена платного билета, ₽ | B8: =Билеты!$B$19 -> 2427.6042 | C8: =Билеты!$B$19 -> 2427.6042 | D8: =Билеты!$B$19 -> 2427.6042 | E8: =Билеты!$B$19 -> 2427.6042 | F8: =Билеты!$B$19 -> 2427.6042
A9: 1. ВАЛОВОЙ СБОР | B9: =B7*B8 -> 276746.88 | C9: =Билеты!$F$12 -> 466100 | D9: =D7*D8 -> 623894.27 | E9: =E7*E8 -> 691867.19 | F9: =F7*F8 -> 650597.92
A10: 2. Налоги УСН 6% | B10: =-B9*Вводные!$B$18 -> -16604.812 | C10: =-C9*Вводные!$B$18 -> -27966 | D10: =-D9*Вводные!$B$18 -> -37433.656 | E10: =-E9*Вводные!$B$18 -> -41512.031 | F10: =-F9*Вводные!$B$18 -> -39035.875
A11: 3. Отчисления в РАО 8% | B11: =-B9*Вводные!$B$19 -> -22139.75 | C11: =-C9*Вводные!$B$19 -> -37288 | D11: =-D9*Вводные!$B$19 -> -49911.542 | E11: =-E9*Вводные!$B$19 -> -55349.375 | F11: =-F9*Вводные!$B$19 -> -52047.833
A12: 4. Технические расходы | B12: =-IF(Вводные!$B$22="Фиксированной суммой",Вводные!$B$23,Технические!$E$22) -> -154500 | C12: =-IF(Вводные!$B$22="Фиксированной суммой",Вводные!$B$23,Технические!$E$22) -> -154500 | D12: =-IF(Вводные!$B$22="Фиксированной суммой",Вводные!$B$23,Технические!$E$22) -> -154500 | E12: =-IF(Вводные!$B$22="Фиксированной суммой",Вводные!$B$23,Технические!$E$22) -> -154500 | F12: =-IF(Вводные!$B$22="Фиксированной суммой",Вводные!$B$23,Технические!$E$22) -> -154500
A13: гонорары — если до раздела | B13: =-IF(Вводные!$B$37="Да",Гонорары!$E$13,0) -> 0 | C13: =-IF(Вводные!$B$37="Да",Гонорары!$E$13,0) -> 0 | D13: =-IF(Вводные!$B$37="Да",Гонорары!$E$13,0) -> 0 | E13: =-IF(Вводные!$B$37="Да",Гонорары!$E$13,0) -> 0 | F13: =-IF(Вводные!$B$37="Да",Гонорары!$E$13,0) -> 0
A14: маркетинг — если до раздела | B14: =-IF(Вводные!$B$38="Да",Маркетинг!$B$14,0) -> 0 | C14: =-IF(Вводные!$B$38="Да",Маркетинг!$B$14,0) -> 0 | D14: =-IF(Вводные!$B$38="Да",Маркетинг!$B$14,0) -> 0 | E14: =-IF(Вводные!$B$38="Да",Маркетинг!$B$14,0) -> 0 | F14: =-IF(Вводные!$B$38="Да",Маркетинг!$B$14,0) -> 0
A15: прочие — если до раздела | B15: =-IF(Вводные!$B$39="Да",Прочие!$E$19,0) -> 0 | C15: =-IF(Вводные!$B$39="Да",Прочие!$E$19,0) -> 0 | D15: =-IF(Вводные!$B$39="Да",Прочие!$E$19,0) -> 0 | E15: =-IF(Вводные!$B$39="Да",Прочие!$E$19,0) -> 0 | F15: =-IF(Вводные!$B$39="Да",Прочие!$E$19,0) -> 0
A16: 5. ПРИБЫЛЬ | B16: =SUM(B9:B15) -> 83502.312 | C16: =SUM(C9:C15) -> 246346 | D16: =SUM(D9:D15) -> 382049.07 | E16: =SUM(E9:E15) -> 440505.78 | F16: =SUM(F9:F15) -> 405014.21 | G16: Именно эта строка делится с площадкой пополам
A17: доля площадки | B17: =-IF(B16>=0,B16*Вводные!$B$27,IF(Вводные!$B$28="Да",B16*Вводные!$B$27,0)) -> -41751.156 | C17: =-IF(C16>=0,C16*Вводные!$B$27,IF(Вводные!$B$28="Да",C16*Вводные!$B$27,0)) -> -123173 | D17: =-IF(D16>=0,D16*Вводные!$B$27,IF(Вводные!$B$28="Да",D16*Вводные!$B$27,0)) -> -191024.54 | E17: =-IF(E16>=0,E16*Вводные!$B$27,IF(Вводные!$B$28="Да",E16*Вводные!$B$27,0)) -> -220252.89 | F17: =-IF(F16>=0,F16*Вводные!$B$27,IF(Вводные!$B$28="Да",F16*Вводные!$B$27,0)) -> -202507.1
A18: ПРИБЫЛЬ ОРГАНИЗАТОРА | B18: =B16+B17 -> 41751.156 | C18: =C16+C17 -> 123173 | D18: =D16+D17 -> 191024.54 | E18: =E16+E17 -> 220252.89 | F18: =F16+F17 -> 202507.1 | G18: База для всех вычетов этапа 2
A19: налоги 7% | B19: =-MAX(0,B18)*Вводные!$B$31 -> -2922.5809 | C19: =-MAX(0,C18)*Вводные!$B$31 -> -8622.11 | D19: =-MAX(0,D18)*Вводные!$B$31 -> -13371.718 | E19: =-MAX(0,E18)*Вводные!$B$31 -> -15417.702 | F19: =-MAX(0,F18)*Вводные!$B$31 -> -14175.497
A20: банковские комиссии 1% | B20: =-MAX(0,B18)*Вводные!$B$32 -> -417.51156 | C20: =-MAX(0,C18)*Вводные!$B$32 -> -1231.73 | D20: =-MAX(0,D18)*Вводные!$B$32 -> -1910.2454 | E20: =-MAX(0,E18)*Вводные!$B$32 -> -2202.5289 | F20: =-MAX(0,F18)*Вводные!$B$32 -> -2025.071
A21: гонорары артистам | B21: =-IF(Вводные!$B$37="Нет",Гонорары!$E$13,0) -> -49000 | C21: =-IF(Вводные!$B$37="Нет",Гонорары!$E$13,0) -> -49000 | D21: =-IF(Вводные!$B$37="Нет",Гонорары!$E$13,0) -> -49000 | E21: =-IF(Вводные!$B$37="Нет",Гонорары!$E$13,0) -> -49000 | F21: =-IF(Вводные!$B$37="Нет",Гонорары!$E$13,0) -> -49000
A22: маркетинг и PR | B22: =-IF(Вводные!$B$38="Нет",Маркетинг!$B$14,0) -> -60000 | C22: =-IF(Вводные!$B$38="Нет",Маркетинг!$B$14,0) -> -60000 | D22: =-IF(Вводные!$B$38="Нет",Маркетинг!$B$14,0) -> -60000 | E22: =-IF(Вводные!$B$38="Нет",Маркетинг!$B$14,0) -> -60000 | F22: =-IF(Вводные!$B$38="Нет",Маркетинг!$B$14,0) -> -60000
A23: прочие расходы | B23: =-IF(Вводные!$B$39="Нет",Прочие!$E$19,0) -> -76450 | C23: =-IF(Вводные!$B$39="Нет",Прочие!$E$19,0) -> -76450 | D23: =-IF(Вводные!$B$39="Нет",Прочие!$E$19,0) -> -76450 | E23: =-IF(Вводные!$B$39="Нет",Прочие!$E$19,0) -> -76450 | F23: =-IF(Вводные!$B$39="Нет",Прочие!$E$19,0) -> -76450
A24: ЧИСТЫЙ ДОХОД ОРГАНИЗАТОРА | B24: =B18+SUM(B19:B23) -> -147038.94 | C24: =C18+SUM(C19:C23) -> -72130.84 | D24: =D18+SUM(D19:D23) -> -9707.4265 | E24: =E18+SUM(E19:E23) -> 17182.659 | F24: =F18+SUM(F19:F23) -> 856.53583 | G24: Деньги, которые реально останутся у вас
A25: Рентабельность к валовому сбору, % | B25: =IFERROR(B24/B9,0) -> -0.531312 | C25: =IFERROR(C24/C9,0) -> -0.154754 | D25: =IFERROR(D24/D9,0) -> -0.01555941 | E25: =IFERROR(E24/E9,0) -> 0.024835199 | F25: =IFERROR(F24/F9,0) -> 0.0013165364
A26: Отклонение от базового сценария, ₽ | B26: =B24-$C$24 -> -74908.096 | C26: =C24-$C$24 -> 0 | D26: =D24-$C$24 -> 62423.414 | E26: =E24-$C$24 -> 89313.499 | F26: =F24-$C$24 -> 72987.376

Sheet Чувствительность
A1: ЧУВСТВИТЕЛЬНОСТЬ: ЦЕНА ПРОТИВ ЗАПОЛНЯЕМОСТИ
A2: Зелёное — прибыль, красное — убыток. Верхняя таблица — прибыль до раздела, нижняя — то, что остаётся организатору после раздела и расходов этапа 2.
A4: ПРИБЫЛЬ ДО РАЗДЕЛА С ПЛОЩАДКОЙ (этап 1), ₽
A5: Заполняемость \ Средняя цена | B5: 1500 | C5: 2000 | D5: 2500 | E5: 3000 | F5: 3500 | G5: 4000 | H5: 4500
A6: 0.3 | B6: =(Вводные!$B$12*$A6*Билеты!$B$22*B$5)*(1-Вводные!$B$18-Вводные!$B$19)-Экономика!$C$75 -> -44147.525 | C6: =(Вводные!$B$12*$A6*Билеты!$B$22*C$5)*(1-Вводные!$B$18-Вводные!$B$19)-Экономика!$C$75 -> -7363.3663 | D6: =(Вводные!$B$12*$A6*Билеты!$B$22*D$5)*(1-Вводные!$B$18-Вводные!$B$19)-Экономика!$C$75 -> 29420.792 | E6: =(Вводные!$B$12*$A6*Билеты!$B$22*E$5)*(1-Вводные!$B$18-Вводные!$B$19)-Экономика!$C$75 -> 66204.95 | F6: =(Вводные!$B$12*$A6*Билеты!$B$22*F$5)*(1-Вводные!$B$18-Вводные!$B$19)-Экономика!$C$75 -> 102989.11 | G6: =(Вводные!$B$12*$A6*Билеты!$B$22*G$5)*(1-Вводные!$B$18-Вводные!$B$19)-Экономика!$C$75 -> 139773.27 | H6: =(Вводные!$B$12*$A6*Билеты!$B$22*H$5)*(1-Вводные!$B$18-Вводные!$B$19)-Экономика!$C$75 -> 176557.43
A7: 0.4 | B7: =(Вводные!$B$12*$A7*Билеты!$B$22*B$5)*(1-Вводные!$B$18-Вводные!$B$19)-Экономика!$C$75 -> -7363.3663 | C7: =(Вводные!$B$12*$A7*Билеты!$B$22*C$5)*(1-Вводные!$B$18-Вводные!$B$19)-Экономика!$C$75 -> 41682.178 | D7: =(Вводные!$B$12*$A7*Билеты!$B$22*D$5)*(1-Вводные!$B$18-Вводные!$B$19)-Экономика!$C$75 -> 90727.723 | E7: =(Вводные!$B$12*$A7*Билеты!$B$22*E$5)*(1-Вводные!$B$18-Вводные!$B$19)-Экономика!$C$75 -> 139773.27 | F7: =(Вводные!$B$12*$A7*Билеты!$B$22*F$5)*(1-Вводные!$B$18-Вводные!$B$19)-Экономика!$C$75 -> 188818.81 | G7: =(Вводные!$B$12*$A7*Билеты!$B$22*G$5)*(1-Вводные!$B$18-Вводные!$B$19)-Экономика!$C$75 -> 237864.36 | H7: =(Вводные!$B$12*$A7*Билеты!$B$22*H$5)*(1-Вводные!$B$18-Вводные!$B$19)-Экономика!$C$75 -> 286909.9
A8: 0.5 | B8: =(Вводные!$B$12*$A8*Билеты!$B$22*B$5)*(1-Вводные!$B$18-Вводные!$B$19)-Экономика!$C$75 -> 29420.792 | C8: =(Вводные!$B$12*$A8*Билеты!$B$22*C$5)*(1-Вводные!$B$18-Вводные!$B$19)-Экономика!$C$75 -> 90727.723 | D8: =(Вводные!$B$12*$A8*Билеты!$B$22*D$5)*(1-Вводные!$B$18-Вводные!$B$19)-Экономика!$C$75 -> 152034.65 | E8: =(Вводные!$B$12*$A8*Билеты!$B$22*E$5)*(1-Вводные!$B$18-Вводные!$B$19)-Экономика!$C$75 -> 213341.58 | F8: =(Вводные!$B$12*$A8*Билеты!$B$22*F$5)*(1-Вводные!$B$18-Вводные!$B$19)-Экономика!$C$75 -> 274648.51 | G8: =(Вводные!$B$12*$A8*Билеты!$B$22*G$5)*(1-Вводные!$B$18-Вводные!$B$19)-Экономика!$C$75 -> 335955.45 | H8: =(Вводные!$B$12*$A8*Билеты!$B$22*H$5)*(1-Вводные!$B$18-Вводные!$B$19)-Экономика!$C$75 -> 397262.38
A9: 0.6 | B9: =(Вводные!$B$12*$A9*Билеты!$B$22*B$5)*(1-Вводные!$B$18-Вводные!$B$19)-Экономика!$C$75 -> 66204.95 | C9: =(Вводные!$B$12*$A9*Билеты!$B$22*C$5)*(1-Вводные!$B$18-Вводные!$B$19)-Экономика!$C$75 -> 139773.27 | D9: =(Вводные!$B$12*$A9*Билеты!$B$22*D$5)*(1-Вводные!$B$18-Вводные!$B$19)-Экономика!$C$75 -> 213341.58 | E9: =(Вводные!$B$12*$A9*Билеты!$B$22*E$5)*(1-Вводные!$B$18-Вводные!$B$19)-Экономика!$C$75 -> 286909.9 | F9: =(Вводные!$B$12*$A9*Билеты!$B$22*F$5)*(1-Вводные!$B$18-Вводные!$B$19)-Экономика!$C$75 -> 360478.22 | G9: =(Вводные!$B$12*$A9*Билеты!$B$22*G$5)*(1-Вводные!$B$18-Вводные!$B$19)-Экономика!$C$75 -> 434046.53 | H9: =(Вводные!$B$12*$A9*Билеты!$B$22*H$5)*(1-Вводные!$B$18-Вводные!$B$19)-Экономика!$C$75 -> 507614.85
A10: 0.7 | B10: =(Вводные!$B$12*$A10*Билеты!$B$22*B$5)*(1-Вводные!$B$18-Вводные!$B$19)-Экономика!$C$75 -> 102989.11 | C10: =(Вводные!$B$12*$A10*Билеты!$B$22*C$5)*(1-Вводные!$B$18-Вводные!$B$19)-Экономика!$C$75 -> 188818.81 | D10: =(Вводные!$B$12*$A10*Билеты!$B$22*D$5)*(1-Вводные!$B$18-Вводные!$B$19)-Экономика!$C$75 -> 274648.51 | E10: =(Вводные!$B$12*$A10*Билеты!$B$22*E$5)*(1-Вводные!$B$18-Вводные!$B$19)-Экономика!$C$75 -> 360478.22 | F10: =(Вводные!$B$12*$A10*Билеты!$B$22*F$5)*(1-Вводные!$B$18-Вводные!$B$19)-Экономика!$C$75 -> 446307.92 | G10: =(Вводные!$B$12*$A10*Билеты!$B$22*G$5)*(1-Вводные!$B$18-Вводные!$B$19)-Экономика!$C$75 -> 532137.62 | H10: =(Вводные!$B$12*$A10*Билеты!$B$22*H$5)*(1-Вводные!$B$18-Вводные!$B$19)-Экономика!$C$75 -> 617967.33
A11: 0.8 | B11: =(Вводные!$B$12*$A11*Билеты!$B$22*B$5)*(1-Вводные!$B$18-Вводные!$B$19)-Экономика!$C$75 -> 139773.27 | C11: =(Вводные!$B$12*$A11*Билеты!$B$22*C$5)*(1-Вводные!$B$18-Вводные!$B$19)-Экономика!$C$75 -> 237864.36 | D11: =(Вводные!$B$12*$A11*Билеты!$B$22*D$5)*(1-Вводные!$B$18-Вводные!$B$19)-Экономика!$C$75 -> 335955.45 | E11: =(Вводные!$B$12*$A11*Билеты!$B$22*E$5)*(1-Вводные!$B$18-Вводные!$B$19)-Экономика!$C$75 -> 434046.53 | F11: =(Вводные!$B$12*$A11*Билеты!$B$22*F$5)*(1-Вводные!$B$18-Вводные!$B$19)-Экономика!$C$75 -> 532137.62 | G11: =(Вводные!$B$12*$A11*Билеты!$B$22*G$5)*(1-Вводные!$B$18-Вводные!$B$19)-Экономика!$C$75 -> 630228.71 | H11: =(Вводные!$B$12*$A11*Билеты!$B$22*H$5)*(1-Вводные!$B$18-Вводные!$B$19)-Экономика!$C$75 -> 728319.8
A12: 0.9 | B12: =(Вводные!$B$12*$A12*Билеты!$B$22*B$5)*(1-Вводные!$B$18-Вводные!$B$19)-Экономика!$C$75 -> 176557.43 | C12: =(Вводные!$B$12*$A12*Билеты!$B$22*C$5)*(1-Вводные!$B$18-Вводные!$B$19)-Экономика!$C$75 -> 286909.9 | D12: =(Вводные!$B$12*$A12*Билеты!$B$22*D$5)*(1-Вводные!$B$18-Вводные!$B$19)-Экономика!$C$75 -> 397262.38 | E12: =(Вводные!$B$12*$A12*Билеты!$B$22*E$5)*(1-Вводные!$B$18-Вводные!$B$19)-Экономика!$C$75 -> 507614.85 | F12: =(Вводные!$B$12*$A12*Билеты!$B$22*F$5)*(1-Вводные!$B$18-Вводные!$B$19)-Экономика!$C$75 -> 617967.33 | G12: =(Вводные!$B$12*$A12*Билеты!$B$22*G$5)*(1-Вводные!$B$18-Вводные!$B$19)-Экономика!$C$75 -> 728319.8 | H12: =(Вводные!$B$12*$A12*Билеты!$B$22*H$5)*(1-Вводные!$B$18-Вводные!$B$19)-Экономика!$C$75 -> 838672.28
A13: 1 | B13: =(Вводные!$B$12*$A13*Билеты!$B$22*B$5)*(1-Вводные!$B$18-Вводные!$B$19)-Экономика!$C$75 -> 213341.58 | C13: =(Вводные!$B$12*$A13*Билеты!$B$22*C$5)*(1-Вводные!$B$18-Вводные!$B$19)-Экономика!$C$75 -> 335955.45 | D13: =(Вводные!$B$12*$A13*Билеты!$B$22*D$5)*(1-Вводные!$B$18-Вводные!$B$19)-Экономика!$C$75 -> 458569.31 | E13: =(Вводные!$B$12*$A13*Билеты!$B$22*E$5)*(1-Вводные!$B$18-Вводные!$B$19)-Экономика!$C$75 -> 581183.17 | F13: =(Вводные!$B$12*$A13*Билеты!$B$22*F$5)*(1-Вводные!$B$18-Вводные!$B$19)-Экономика!$C$75 -> 703797.03 | G13: =(Вводные!$B$12*$A13*Билеты!$B$22*G$5)*(1-Вводные!$B$18-Вводные!$B$19)-Экономика!$C$75 -> 826410.89 | H13: =(Вводные!$B$12*$A13*Билеты!$B$22*H$5)*(1-Вводные!$B$18-Вводные!$B$19)-Экономика!$C$75 -> 949024.75
A15: ЧИСТЫЙ ДОХОД ОРГАНИЗАТОРА после раздела и расходов этапа 2, ₽
A16: Заполняемость \ Средняя цена | B16: 1500 | C16: 2000 | D16: 2500 | E16: 3000 | F16: 3500 | G16: 4000 | H16: 4500
A17: 0.3 | B17: =IF(B6>=0,B6*Вводные!$B$26,IF(Вводные!$B$28="Да",B6*Вводные!$B$26,B6))-MAX(0,IF(B6>=0,B6*Вводные!$B$26,IF(Вводные!$B$28="Да",B6*Вводные!$B$26,B6)))*Вводные!$B$33-Экономика!$C$76 -> -229597.52 | C17: =IF(C6>=0,C6*Вводные!$B$26,IF(Вводные!$B$28="Да",C6*Вводные!$B$26,C6))-MAX(0,IF(C6>=0,C6*Вводные!$B$26,IF(Вводные!$B$28="Да",C6*Вводные!$B$26,C6)))*Вводные!$B$33-Экономика!$C$76 -> -192813.37 | D17: =IF(D6>=0,D6*Вводные!$B$26,IF(Вводные!$B$28="Да",D6*Вводные!$B$26,D6))-MAX(0,IF(D6>=0,D6*Вводные!$B$26,IF(Вводные!$B$28="Да",D6*Вводные!$B$26,D6)))*Вводные!$B$33-Экономика!$C$76 -> -171916.44 | E17: =IF(E6>=0,E6*Вводные!$B$26,IF(Вводные!$B$28="Да",E6*Вводные!$B$26,E6))-MAX(0,IF(E6>=0,E6*Вводные!$B$26,IF(Вводные!$B$28="Да",E6*Вводные!$B$26,E6)))*Вводные!$B$33-Экономика!$C$76 -> -154995.72 | F17: =IF(F6>=0,F6*Вводные!$B$26,IF(Вводные!$B$28="Да",F6*Вводные!$B$26,F6))-MAX(0,IF(F6>=0,F6*Вводные!$B$26,IF(Вводные!$B$28="Да",F6*Вводные!$B$26,F6)))*Вводные!$B$33-Экономика!$C$76 -> -138075.01 | G17: =IF(G6>=0,G6*Вводные!$B$26,IF(Вводные!$B$28="Да",G6*Вводные!$B$26,G6))-MAX(0,IF(G6>=0,G6*Вводные!$B$26,IF(Вводные!$B$28="Да",G6*Вводные!$B$26,G6)))*Вводные!$B$33-Экономика!$C$76 -> -121154.3 | H17: =IF(H6>=0,H6*Вводные!$B$26,IF(Вводные!$B$28="Да",H6*Вводные!$B$26,H6))-MAX(0,IF(H6>=0,H6*Вводные!$B$26,IF(Вводные!$B$28="Да",H6*Вводные!$B$26,H6)))*Вводные!$B$33-Экономика!$C$76 -> -104233.58
A18: 0.4 | B18: =IF(B7>=0,B7*Вводные!$B$26,IF(Вводные!$B$28="Да",B7*Вводные!$B$26,B7))-MAX(0,IF(B7>=0,B7*Вводные!$B$26,IF(Вводные!$B$28="Да",B7*Вводные!$B$26,B7)))*Вводные!$B$33-Экономика!$C$76 -> -192813.37 | C18: =IF(C7>=0,C7*Вводные!$B$26,IF(Вводные!$B$28="Да",C7*Вводные!$B$26,C7))-MAX(0,IF(C7>=0,C7*Вводные!$B$26,IF(Вводные!$B$28="Да",C7*Вводные!$B$26,C7)))*Вводные!$B$33-Экономика!$C$76 -> -166276.2 | D18: =IF(D7>=0,D7*Вводные!$B$26,IF(Вводные!$B$28="Да",D7*Вводные!$B$26,D7))-MAX(0,IF(D7>=0,D7*Вводные!$B$26,IF(Вводные!$B$28="Да",D7*Вводные!$B$26,D7)))*Вводные!$B$33-Экономика!$C$76 -> -143715.25 | E18: =IF(E7>=0,E7*Вводные!$B$26,IF(Вводные!$B$28="Да",E7*Вводные!$B$26,E7))-MAX(0,IF(E7>=0,E7*Вводные!$B$26,IF(Вводные!$B$28="Да",E7*Вводные!$B$26,E7)))*Вводные!$B$33-Экономика!$C$76 -> -121154.3 | F18: =IF(F7>=0,F7*Вводные!$B$26,IF(Вводные!$B$28="Да",F7*Вводные!$B$26,F7))-MAX(0,IF(F7>=0,F7*Вводные!$B$26,IF(Вводные!$B$28="Да",F7*Вводные!$B$26,F7)))*Вводные!$B$33-Экономика!$C$76 -> -98593.347 | G18: =IF(G7>=0,G7*Вводные!$B$26,IF(Вводные!$B$28="Да",G7*Вводные!$B$26,G7))-MAX(0,IF(G7>=0,G7*Вводные!$B$26,IF(Вводные!$B$28="Да",G7*Вводные!$B$26,G7)))*Вводные!$B$33-Экономика!$C$76 -> -76032.396 | H18: =IF(H7>=0,H7*Вводные!$B$26,IF(Вводные!$B$28="Да",H7*Вводные!$B$26,H7))-MAX(0,IF(H7>=0,H7*Вводные!$B$26,IF(Вводные!$B$28="Да",H7*Вводные!$B$26,H7)))*Вводные!$B$33-Экономика!$C$76 -> -53471.446
A19: 0.5 | B19: =IF(B8>=0,B8*Вводные!$B$26,IF(Вводные!$B$28="Да",B8*Вводные!$B$26,B8))-MAX(0,IF(B8>=0,B8*Вводные!$B$26,IF(Вводные!$B$28="Да",B8*Вводные!$B$26,B8)))*Вводные!$B$33-Экономика!$C$76 -> -171916.44 | C19: =IF(C8>=0,C8*Вводные!$B$26,IF(Вводные!$B$28="Да",C8*Вводные!$B$26,C8))-MAX(0,IF(C8>=0,C8*Вводные!$B$26,IF(Вводные!$B$28="Да",C8*Вводные!$B$26,C8)))*Вводные!$B$33-Экономика!$C$76 -> -143715.25 | D19: =IF(D8>=0,D8*Вводные!$B$26,IF(Вводные!$B$28="Да",D8*Вводные!$B$26,D8))-MAX(0,IF(D8>=0,D8*Вводные!$B$26,IF(Вводные!$B$28="Да",D8*Вводные!$B$26,D8)))*Вводные!$B$33-Экономика!$C$76 -> -115514.06 | E19: =IF(E8>=0,E8*Вводные!$B$26,IF(Вводные!$B$28="Да",E8*Вводные!$B$26,E8))-MAX(0,IF(E8>=0,E8*Вводные!$B$26,IF(Вводные!$B$28="Да",E8*Вводные!$B$26,E8)))*Вводные!$B$33-Экономика!$C$76 -> -87312.871 | F19: =IF(F8>=0,F8*Вводные!$B$26,IF(Вводные!$B$28="Да",F8*Вводные!$B$26,F8))-MAX(0,IF(F8>=0,F8*Вводные!$B$26,IF(Вводные!$B$28="Да",F8*Вводные!$B$26,F8)))*Вводные!$B$33-Экономика!$C$76 -> -59111.683 | G19: =IF(G8>=0,G8*Вводные!$B$26,IF(Вводные!$B$28="Да",G8*Вводные!$B$26,G8))-MAX(0,IF(G8>=0,G8*Вводные!$B$26,IF(Вводные!$B$28="Да",G8*Вводные!$B$26,G8)))*Вводные!$B$33-Экономика!$C$76 -> -30910.495 | H19: =IF(H8>=0,H8*Вводные!$B$26,IF(Вводные!$B$28="Да",H8*Вводные!$B$26,H8))-MAX(0,IF(H8>=0,H8*Вводные!$B$26,IF(Вводные!$B$28="Да",H8*Вводные!$B$26,H8)))*Вводные!$B$33-Экономика!$C$76 -> -2709.3069
A20: 0.6 | B20: =IF(B9>=0,B9*Вводные!$B$26,IF(Вводные!$B$28="Да",B9*Вводные!$B$26,B9))-MAX(0,IF(B9>=0,B9*Вводные!$B$26,IF(Вводные!$B$28="Да",B9*Вводные!$B$26,B9)))*Вводные!$B$33-Экономика!$C$76 -> -154995.72 | C20: =IF(C9>=0,C9*Вводные!$B$26,IF(Вводные!$B$28="Да",C9*Вводные!$B$26,C9))-MAX(0,IF(C9>=0,C9*Вводные!$B$26,IF(Вводные!$B$28="Да",C9*Вводные!$B$26,C9)))*Вводные!$B$33-Экономика!$C$76 -> -121154.3 | D20: =IF(D9>=0,D9*Вводные!$B$26,IF(Вводные!$B$28="Да",D9*Вводные!$B$26,D9))-MAX(0,IF(D9>=0,D9*Вводные!$B$26,IF(Вводные!$B$28="Да",D9*Вводные!$B$26,D9)))*Вводные!$B$33-Экономика!$C$76 -> -87312.871 | E20: =IF(E9>=0,E9*Вводные!$B$26,IF(Вводные!$B$28="Да",E9*Вводные!$B$26,E9))-MAX(0,IF(E9>=0,E9*Вводные!$B$26,IF(Вводные!$B$28="Да",E9*Вводные!$B$26,E9)))*Вводные!$B$33-Экономика!$C$76 -> -53471.446 | F20: =IF(F9>=0,F9*Вводные!$B$26,IF(Вводные!$B$28="Да",F9*Вводные!$B$26,F9))-MAX(0,IF(F9>=0,F9*Вводные!$B$26,IF(Вводные!$B$28="Да",F9*Вводные!$B$26,F9)))*Вводные!$B$33-Экономика!$C$76 -> -19630.02 | G20: =IF(G9>=0,G9*Вводные!$B$26,IF(Вводные!$B$28="Да",G9*Вводные!$B$26,G9))-MAX(0,IF(G9>=0,G9*Вводные!$B$26,IF(Вводные!$B$28="Да",G9*Вводные!$B$26,G9)))*Вводные!$B$33-Экономика!$C$76 -> 14211.406 | H20: =IF(H9>=0,H9*Вводные!$B$26,IF(Вводные!$B$28="Да",H9*Вводные!$B$26,H9))-MAX(0,IF(H9>=0,H9*Вводные!$B$26,IF(Вводные!$B$28="Да",H9*Вводные!$B$26,H9)))*Вводные!$B$33-Экономика!$C$76 -> 48052.832
A21: 0.7 | B21: =IF(B10>=0,B10*Вводные!$B$26,IF(Вводные!$B$28="Да",B10*Вводные!$B$26,B10))-MAX(0,IF(B10>=0,B10*Вводные!$B$26,IF(Вводные!$B$28="Да",B10*Вводные!$B$26,B10)))*Вводные!$B$33-Экономика!$C$76 -> -138075.01 | C21: =IF(C10>=0,C10*Вводные!$B$26,IF(Вводные!$B$28="Да",C10*Вводные!$B$26,C10))-MAX(0,IF(C10>=0,C10*Вводные!$B$26,IF(Вводные!$B$28="Да",C10*Вводные!$B$26,C10)))*Вводные!$B$33-Экономика!$C$76 -> -98593.347 | D21: =IF(D10>=0,D10*Вводные!$B$26,IF(Вводные!$B$28="Да",D10*Вводные!$B$26,D10))-MAX(0,IF(D10>=0,D10*Вводные!$B$26,IF(Вводные!$B$28="Да",D10*Вводные!$B$26,D10)))*Вводные!$B$33-Экономика!$C$76 -> -59111.683 | E21: =IF(E10>=0,E10*Вводные!$B$26,IF(Вводные!$B$28="Да",E10*Вводные!$B$26,E10))-MAX(0,IF(E10>=0,E10*Вводные!$B$26,IF(Вводные!$B$28="Да",E10*Вводные!$B$26,E10)))*Вводные!$B$33-Экономика!$C$76 -> -19630.02 | F21: =IF(F10>=0,F10*Вводные!$B$26,IF(Вводные!$B$28="Да",F10*Вводные!$B$26,F10))-MAX(0,IF(F10>=0,F10*Вводные!$B$26,IF(Вводные!$B$28="Да",F10*Вводные!$B$26,F10)))*Вводные!$B$33-Экономика!$C$76 -> 19851.644 | G21: =IF(G10>=0,G10*Вводные!$B$26,IF(Вводные!$B$28="Да",G10*Вводные!$B$26,G10))-MAX(0,IF(G10>=0,G10*Вводные!$B$26,IF(Вводные!$B$28="Да",G10*Вводные!$B$26,G10)))*Вводные!$B$33-Экономика!$C$76 -> 59333.307 | H21: =IF(H10>=0,H10*Вводные!$B$26,IF(Вводные!$B$28="Да",H10*Вводные!$B$26,H10))-MAX(0,IF(H10>=0,H10*Вводные!$B$26,IF(Вводные!$B$28="Да",H10*Вводные!$B$26,H10)))*Вводные!$B$33-Экономика!$C$76 -> 98814.97
A22: 0.8 | B22: =IF(B11>=0,B11*Вводные!$B$26,IF(Вводные!$B$28="Да",B11*Вводные!$B$26,B11))-MAX(0,IF(B11>=0,B11*Вводные!$B$26,IF(Вводные!$B$28="Да",B11*Вводные!$B$26,B11)))*Вводные!$B$33-Экономика!$C$76 -> -121154.3 | C22: =IF(C11>=0,C11*Вводные!$B$26,IF(Вводные!$B$28="Да",C11*Вводные!$B$26,C11))-MAX(0,IF(C11>=0,C11*Вводные!$B$26,IF(Вводные!$B$28="Да",C11*Вводные!$B$26,C11)))*Вводные!$B$33-Экономика!$C$76 -> -76032.396 | D22: =IF(D11>=0,D11*Вводные!$B$26,IF(Вводные!$B$28="Да",D11*Вводные!$B$26,D11))-MAX(0,IF(D11>=0,D11*Вводные!$B$26,IF(Вводные!$B$28="Да",D11*Вводные!$B$26,D11)))*Вводные!$B$33-Экономика!$C$76 -> -30910.495 | E22: =IF(E11>=0,E11*Вводные!$B$26,IF(Вводные!$B$28="Да",E11*Вводные!$B$26,E11))-MAX(0,IF(E11>=0,E11*Вводные!$B$26,IF(Вводные!$B$28="Да",E11*Вводные!$B$26,E11)))*Вводные!$B$33-Экономика!$C$76 -> 14211.406 | F22: =IF(F11>=0,F11*Вводные!$B$26,IF(Вводные!$B$28="Да",F11*Вводные!$B$26,F11))-MAX(0,IF(F11>=0,F11*Вводные!$B$26,IF(Вводные!$B$28="Да",F11*Вводные!$B$26,F11)))*Вводные!$B$33-Экономика!$C$76 -> 59333.307 | G22: =IF(G11>=0,G11*Вводные!$B$26,IF(Вводные!$B$28="Да",G11*Вводные!$B$26,G11))-MAX(0,IF(G11>=0,G11*Вводные!$B$26,IF(Вводные!$B$28="Да",G11*Вводные!$B$26,G11)))*Вводные!$B$33-Экономика!$C$76 -> 104455.21 | H22: =IF(H11>=0,H11*Вводные!$B$26,IF(Вводные!$B$28="Да",H11*Вводные!$B$26,H11))-MAX(0,IF(H11>=0,H11*Вводные!$B$26,IF(Вводные!$B$28="Да",H11*Вводные!$B$26,H11)))*Вводные!$B$33-Экономика!$C$76 -> 149577.11
A23: 0.9 | B23: =IF(B12>=0,B12*Вводные!$B$26,IF(Вводные!$B$28="Да",B12*Вводные!$B$26,B12))-MAX(0,IF(B12>=0,B12*Вводные!$B$26,IF(Вводные!$B$28="Да",B12*Вводные!$B$26,B12)))*Вводные!$B$33-Экономика!$C$76 -> -104233.58 | C23: =IF(C12>=0,C12*Вводные!$B$26,IF(Вводные!$B$28="Да",C12*Вводные!$B$26,C12))-MAX(0,IF(C12>=0,C12*Вводные!$B$26,IF(Вводные!$B$28="Да",C12*Вводные!$B$26,C12)))*Вводные!$B$33-Экономика!$C$76 -> -53471.446 | D23: =IF(D12>=0,D12*Вводные!$B$26,IF(Вводные!$B$28="Да",D12*Вводные!$B$26,D12))-MAX(0,IF(D12>=0,D12*Вводные!$B$26,IF(Вводные!$B$28="Да",D12*Вводные!$B$26,D12)))*Вводные!$B$33-Экономика!$C$76 -> -2709.3069 | E23: =IF(E12>=0,E12*Вводные!$B$26,IF(Вводные!$B$28="Да",E12*Вводные!$B$26,E12))-MAX(0,IF(E12>=0,E12*Вводные!$B$26,IF(Вводные!$B$28="Да",E12*Вводные!$B$26,E12)))*Вводные!$B$33-Экономика!$C$76 -> 48052.832 | F23: =IF(F12>=0,F12*Вводные!$B$26,IF(Вводные!$B$28="Да",F12*Вводные!$B$26,F12))-MAX(0,IF(F12>=0,F12*Вводные!$B$26,IF(Вводные!$B$28="Да",F12*Вводные!$B$26,F12)))*Вводные!$B$33-Экономика!$C$76 -> 98814.97 | G23: =IF(G12>=0,G12*Вводные!$B$26,IF(Вводные!$B$28="Да",G12*Вводные!$B$26,G12))-MAX(0,IF(G12>=0,G12*Вводные!$B$26,IF(Вводные!$B$28="Да",G12*Вводные!$B$26,G12)))*Вводные!$B$33-Экономика!$C$76 -> 149577.11 | H23: =IF(H12>=0,H12*Вводные!$B$26,IF(Вводные!$B$28="Да",H12*Вводные!$B$26,H12))-MAX(0,IF(H12>=0,H12*Вводные!$B$26,IF(Вводные!$B$28="Да",H12*Вводные!$B$26,H12)))*Вводные!$B$33-Экономика!$C$76 -> 200339.25
A24: 1 | B24: =IF(B13>=0,B13*Вводные!$B$26,IF(Вводные!$B$28="Да",B13*Вводные!$B$26,B13))-MAX(0,IF(B13>=0,B13*Вводные!$B$26,IF(Вводные!$B$28="Да",B13*Вводные!$B$26,B13)))*Вводные!$B$33-Экономика!$C$76 -> -87312.871 | C24: =IF(C13>=0,C13*Вводные!$B$26,IF(Вводные!$B$28="Да",C13*Вводные!$B$26,C13))-MAX(0,IF(C13>=0,C13*Вводные!$B$26,IF(Вводные!$B$28="Да",C13*Вводные!$B$26,C13)))*Вводные!$B$33-Экономика!$C$76 -> -30910.495 | D24: =IF(D13>=0,D13*Вводные!$B$26,IF(Вводные!$B$28="Да",D13*Вводные!$B$26,D13))-MAX(0,IF(D13>=0,D13*Вводные!$B$26,IF(Вводные!$B$28="Да",D13*Вводные!$B$26,D13)))*Вводные!$B$33-Экономика!$C$76 -> 25491.881 | E24: =IF(E13>=0,E13*Вводные!$B$26,IF(Вводные!$B$28="Да",E13*Вводные!$B$26,E13))-MAX(0,IF(E13>=0,E13*Вводные!$B$26,IF(Вводные!$B$28="Да",E13*Вводные!$B$26,E13)))*Вводные!$B$33-Экономика!$C$76 -> 81894.257 | F24: =IF(F13>=0,F13*Вводные!$B$26,IF(Вводные!$B$28="Да",F13*Вводные!$B$26,F13))-MAX(0,IF(F13>=0,F13*Вводные!$B$26,IF(Вводные!$B$28="Да",F13*Вводные!$B$26,F13)))*Вводные!$B$33-Экономика!$C$76 -> 138296.63 | G24: =IF(G13>=0,G13*Вводные!$B$26,IF(Вводные!$B$28="Да",G13*Вводные!$B$26,G13))-MAX(0,IF(G13>=0,G13*Вводные!$B$26,IF(Вводные!$B$28="Да",G13*Вводные!$B$26,G13)))*Вводные!$B$33-Экономика!$C$76 -> 194699.01 | H24: =IF(H13>=0,H13*Вводные!$B$26,IF(Вводные!$B$28="Да",H13*Вводные!$B$26,H13))-MAX(0,IF(H13>=0,H13*Вводные!$B$26,IF(Вводные!$B$28="Да",H13*Вводные!$B$26,H13)))*Вводные!$B$33-Экономика!$C$76 -> 251101.39
A27: Сколько нужно продать при разной средней цене, чтобы выйти в ноль
A28: Средняя цена, ₽ | B28: 1500 | C28: 2000 | D28: 2500 | E28: 3000 | F28: 3500 | G28: 4000 | H28: 4500
A29: Нужно продать платных билетов, шт | B29: =IFERROR(ROUNDUP(Экономика!$C$77/B$28,0),"н/д") -> 433 | C29: =IFERROR(ROUNDUP(Экономика!$C$77/C$28,0),"н/д") -> 325 | D29: =IFERROR(ROUNDUP(Экономика!$C$77/D$28,0),"н/д") -> 260 | E29: =IFERROR(ROUNDUP(Экономика!$C$77/E$28,0),"н/д") -> 217 | F29: =IFERROR(ROUNDUP(Экономика!$C$77/F$28,0),"н/д") -> 186 | G29: =IFERROR(ROUNDUP(Экономика!$C$77/G$28,0),"н/д") -> 163 | H29: =IFERROR(ROUNDUP(Экономика!$C$77/H$28,0),"н/д") -> 145
A30: Это заполняемость зала, % | B30: =IFERROR(B29/Билеты!$B$22/Вводные!$B$12,"н/д") -> 1.5185069 | C30: =IFERROR(C29/Билеты!$B$22/Вводные!$B$12,"н/д") -> 1.1397569 | D30: =IFERROR(D29/Билеты!$B$22/Вводные!$B$12,"н/д") -> 0.91180556 | E30: =IFERROR(E29/Билеты!$B$22/Вводные!$B$12,"н/д") -> 0.76100694 | F30: =IFERROR(F29/Билеты!$B$22/Вводные!$B$12,"н/д") -> 0.65229167 | G30: =IFERROR(G29/Билеты!$B$22/Вводные!$B$12,"н/д") -> 0.57163194 | H30: =IFERROR(H29/Билеты!$B$22/Вводные!$B$12,"н/д") -> 0.50850694

Sheet Варианты
A1: ВАРИАНТЫ УЛУЧШЕНИЯ ЭКОНОМИКИ
A2: Отсортировано по силе влияния. Первые три меняют саму конструкцию сделки — они дают больше, чем любая экономия на смете.
A4: № | B4: Направление | C4: Что конкретно сделать | D4: Где в модели | E4: Оценка эффекта | F4: Что учесть / риск
A5: 1 | B5: Сделка | C5: Вычитать гонорары и маркетинг ДО раздела прибыли. Сейчас площадка получает половину суммы, из которой вы ещё не заплатили ни артистам, ни за рекламу — то есть делит с вами выручку, а не прибыль. | D5: Вводные, раздел 7 — переключатели | E5: Самый сильный рычаг | F5: Это стандартная конструкция ко-промоушена. Главный пункт переговоров
A6: 2 | B6: Сделка | C6: Прописать раздел убытка, а не только прибыли. Сейчас риск асимметричен: прибыль пополам, убыток целиком ваш. | D6: Вводные: «Убыток делится с площадкой» | E6: Снижает риск вдвое | F6: Площадки соглашаются редко, но просить нужно всегда
A7: 3 | B7: Сделка | C7: Сдвинуть долю: 60/40 или 70/30 в вашу пользу, если вы приводите свою аудиторию и несёте маркетинг. | D7: Вводные: «Доля организатора в прибыли» | E7: +10–20 п.п. доли | F7: Аргумент — ваш бюджет маркетинга и ваша база
A8: 4 | B8: РАО | C8: Проверить ставку 8%. Базовый тариф РАО для концертов обычно 5%. Уточнить, не входят ли туда смежные права (ВОИС), и декларировать точный репертуар: собственные произведения возвращаются автору. | D8: Вводные: «Отчисления в РАО» | E8: До 3% от сбора | F8: Нужна корректная рапортичка. Не платить вообще нельзя
A9: 5 | B9: Налоги | C9: Проверить, не возникает ли двойного УСН: 6% на этапе 1 с полной кассы и 7% на этапе 2 с вашей доли. Возможно, форму договора с площадкой можно изменить так, чтобы вашим доходом сразу была ваша доля. | D9: Вводные, разделы 3 и 6 | E9: До 6% от сбора | F9: ОБЯЗАТЕЛЬНО с бухгалтером — зависит от формы договора
A10: 6 | B10: Техника | C10: Разделить технический райдер на «обязательное» и «желательное». Мониторы, свет и видео часто можно упростить без потери качества концерта. | D10: Лист «Технические» | E10: −15–30% сметы | F10: Согласовать с артистом заранее, а не за день
A11: 7 | B11: Техника | C11: Взять звук пакетом у одного подрядчика вместо аренды по позициям. Пакет обычно дешевле суммы строк. | D11: Лист «Технические» | E11: −10–20% сметы | F11: Требуйте в договоре конкретный список оборудования
A12: 8 | B12: Цена | C12: Волновое ценообразование: early bird → предпродажа → цена на входе. Ранняя квота даёт деньги на маркетинг до концерта. | D12: Лист «Билеты», категории 1–3 | E12: +5–10% к сбору | F12: Уже заложено. Разрыв больше 40% обесценивает раннюю цену
A13: 9 | B13: Цена | C13: Поднять цену фан-зоны и добавить в неё мерч или ранний вход. Платят за статус, а не за метры. | D13: Лист «Билеты», строка «Фан-зона / VIP» | E13: +3–7% к сбору | F13: Квота VIP выше 15% зала обычно не продаётся
A14: 10 | B14: Маркетинг | C14: Перераспределить бюджет в каналы с низким CPA: своя база и Telegram обычно в разы дешевле таргета. | D14: Лист «Маркетинг», столбец CPA | E14: −20–30% бюджета | F14: Требует заранее собранной базы
A15: 11 | B15: Маркетинг | C15: Кросс-промо с площадками и артистами смежной аудитории вместо платного охвата. | D15: Лист «Маркетинг», строка с бюджетом 0 | E15: −10–15 тыс ₽ | F15: Договариваться за 4–6 недель
A16: 12 | B16: Гонорары | C16: Перевести часть гонорара в процент от прибыли. Артист разделит риск, а вы снизите постоянные расходы. | D16: Лист «Гонорары» | E16: Снижает точку безубыточности | F16: Работает только со «своими» артистами
... A20: 16 | B20: Риск | C20: Свести платёжный календарь: предоплаты за технику и рекламу уходят до того, как придут деньги за билеты. | D20: Нужен отдельный лист | E20: Убирает кассовый разрыв | F20: Скажите — добавлю календарь по неделям
